Workbook

Sheet Fitting
A1: FITTING CONTAINER 2026 | AT1: 1.6
A2: NO | B2: LOC | C2: CONTAINER | D2: LINER | E2: CHINA FORWARDER | F2: MALAYSIA FORWARDER | G2: CONSIGNEE | H2: FACTORY | I2: PRODUCT | J2: LOADING | K2: ETC | L2: ETD | M2: ETA | N2: ETA DELAY | O2: ATA | P2: STACKED | Q2: FREE DAYS AVAILABLE | T2: INSPECTION | U2: APPROVAL | V2: ORI DOC RECEIVED DATE | W2: K1 SUBMISSION | X2: GATEPASS | Y2: DELIVERY WAREHOUSE | Z2: YARD ARRIVALS | AA2: WAREHOUSE ARRIVALS | AB2: INFORMED COLLECTION | AC2: COLLECTION | AD2: REMARKS 1 | AE2: REMARKS 2 | AF2: REMARKS 3 | AG2: 2ND LABOUR CHARGE | AH2: K1 RATE | AI2: CHINA FORWARDING COST (RMB) | AJ2: PRODUCT VALUE (RMB) | AK2: 0.014 | AL2: DATE RECEIVE K1 | AM2: SST AMOUNT | AN2: LOCAL CLEARANCE CHARGES | AO2: KOPI | AP2: DEMURRAGE | AQ2: PORT CHARGES | AR2: DETENTION | AS2: TOTAL LOCAL CLEARANCE | AT2: TOTAL FREIGHT | AU2: CARGO INSURANCE | AV2: SRT? MBS? BOTH? | AW2: LOCAL CLEARANCE CHARGES | AX2: USD | AY2: SST | BB2: Demurrange | BD2: Detention | BF2: Rate | BG2: System | BH2: Actual | BI2: Diff
A3: =ROW()-2 -> 1 | C3: GXYU5106903 | D3: CMA | E3: Onetouch | F3: MPM | G3: Sorento (Mocha) | H3: Honor | J3: 46182 | K3: 46186 | L3: 46188 | M3: 46194 | N3: 46211 | Q3: 21 | R3: + | S3: 0 | X3: 46211 | AH3: 0.6118 | AI3: 12050 | AJ3: 105240 | AK3: =AJ3*1.4% -> 1473.36 | AL3: 46209 | AM3: 6438.6 | AY3: XY 06/07/2026 17:50PM | BA3: =Q3 -> 21 | BB3: =N3+BA3-1 -> 46231 | BC3: =S3 -> 0 | BD3: =AA3+BC3 -> 0 | BF3: =VLOOKUP(C3,[1]Sheet!$F:$Q,9,FALSE) -> 0.6118 | BG3: =VLOOKUP(C3,[1]Sheet!$F:$Q,5,FALSE) -> 63950 | BH3: =VLOOKUP(C3,[1]Sheet!$F:$Q,12,FALSE) -> 0 | BI3: =BG3-BH3 -> 63950
A4: =ROW()-2 -> 2 | B4: MWH | C4: GXYU5115470 | D4: CMA | E4: Onetouch | F4: Sataka | G4: Sorento | H4: Yanggang | I4: 2406+7547-BL+7547+6047-BL+6047+8047-BL+6647-BL+2435+2435-BL | J4: 46183 | K4: 46186 | L4: 46188 | M4: 46194 | N4: 46215 | Q4: 14 | R4: + | S4: 0 | X4: 46216 | AI4: 11650 | AY4: XY 09/07/2026 9.27AM | BA4: =Q4 -> 14 | BB4: =N4+BA4-1 -> 46228 | BC4: =S4 -> 0 | BD4: =AA4+BC4 -> 0 | BF4: =VLOOKUP(C4,[1]Sheet!$F:$Q,9,FALSE) -> 0.6118 | BG4: =VLOOKUP(C4,[1]Sheet!$F:$Q,5,FALSE) -> 165371 | BH4: =VLOOKUP(C4,[1]Sheet!$F:$Q,12,FALSE) -> 0 | BI4: =BG4-BH4 -> 165371
A5: =ROW()-2 -> 3 | C5: OOCU8630645 | D5: OOCL | E5: Onetouch | F5: Sataka | G5: Sorento | H5: Wenli+Nat Plumbing+Haihuang | J5: 46193 | K5: 46196 | L5: 46198 | M5: 46205 | N5: 46209 | Q5: 21 | R5: + | S5: 0 | X5: 46210 | AI5: 12100 | AY5: XY 02/07/2026 10.43AM | BA5: =Q5 -> 21 | BB5: =N5+BA5-1 -> 46229 | BC5: =S5 -> 0 | BD5: =AA5+BC5 -> 0 | BF5: =VLOOKUP(C5,[1]Sheet!$F:$Q,9,FALSE) -> 0.6059 | BG5: =VLOOKUP(C5,[1]Sheet!$F:$Q,5,FALSE) -> 23400 | BH5: =VLOOKUP(C5,[1]Sheet!$F:$Q,12,FALSE) -> 0 | BI5: =BG5-BH5 -> 23400
A6: =ROW()-2 -> 4 | C6: SEGU4008631 | D6: CMA | E6: Hongxin | F6: MPM | G6: Sorento (Mocha) | H6: Taiyang | J6: 46199 | K6: 46201 | L6: 46204 | M6: 46213 | N6: 46215 | Q6: 14 | R6: + | S6: 0 | X6: 46220 | AH6: 0.6118 | AI6: 11300 | AJ6: 606196 | AK6: =AJ6*1.4% -> 8486.744 | AL6: 46212 | AM6: 37087.1 | AY6: XY 09/07/2026 14.45AM | BA6: =Q6 -> 14 | BB6: =N6+BA6-1 -> 46228 | BC6: =S6 -> 0 | BD6: =AA6+BC6 -> 0 | BF6: =VLOOKUP(C6,[1]Sheet!$F:$Q,9,FALSE) -> 0.6 | BG6: =VLOOKUP(C6,[1]Sheet!$F:$Q,5,FALSE) -> 513090 | BH6: =VLOOKUP(C6,[1]Sheet!$F:$Q,12,FALSE) -> 0 | BI6: =BG6-BH6 -> 513090
A7: =ROW()-2 -> 5 | B7: MWH | C7: GAOU7415150 | D7: MSC | E7: Onetouch | F7: Sataka | G7: Sorento | H7: Yanggang | J7: 46201 | K7: 46203 | L7: 46207 | M7: 46211 | N7: 46213 | Q7: 14 | R7: + | S7: 0 | X7: 46216 | AI7: 12700 | AY7: XY 07/07/2026 03.44PM | BA7: =Q7 -> 14 | BB7: =N7+BA7-1 -> 46226 | BC7: =S7 -> 0 | BD7: =AA7+BC7 -> 0 | BF7: =VLOOKUP(C7,[1]Sheet!$F:$Q,9,FALSE) -> 0.6118 | BG7: =VLOOKUP(C7,[1]Sheet!$F:$Q,5,FALSE) -> 178911 | BH7: =VLOOKUP(C7,[1]Sheet!$F:$Q,12,FALSE) -> 0 | BI7: =BG7-BH7 -> 178911
A8: =ROW()-2 -> 6 | B8: MWH | C8: MSBU6815451 | D8: MSC | E8: Onetouch | F8: Sataka | G8: Sorento | H8: Yanggang | J8: 46201 | K8: 46203 | L8: 46207 | M8: 46211 | N8: 46213 | Q8: 14 | R8: + | S8: 0 | X8: 46216 | AI8: 12700 | AY8: XY 07/07/2026 03.44PM | BA8: =Q8 -> 14 | BB8: =N8+BA8-1 -> 46226 | BC8: =S8 -> 0 | BD8: =AA8+BC8 -> 0 | BF8: =VLOOKUP(C8,[1]Sheet!$F:$Q,9,FALSE) -> 0.6118 | BG8: =VLOOKUP(C8,[1]Sheet!$F:$Q,5,FALSE) -> 140055 | BH8: =VLOOKUP(C8,[1]Sheet!$F:$Q,12,FALSE) -> 0 | BI8: =BG8-BH8 -> 140055
A9: =ROW()-2 -> 7 | C9: DRYU9923315 | D9: ESL | E9: Onetouch | F9: MPM | G9: Sorento (Mocha) | H9: Taiyang | J9: 46206 | K9: 46209 | L9: 46211 | M9: 46217 | N9: 46219 | Q9: 14 | R9: + | S9: 0 | AH9: 0.6027 | AI9: 11900 | AJ9: 507525 | AK9: =AJ9*1.4% -> 7105.35 | AL9: 46218 | AM9: 24838.3 | AY9: XY 15/07/2026 15:29PM | BA9: =Q9 -> 14 | BB9: =N9+BA9-1 -> 46232 | BC9: =S9 -> 0 | BD9: =AA9+BC9 -> 0 | BF9: =VLOOKUP(C9,[1]Sheet!$F:$Q,9,FALSE) -> 0.6027 | BG9: =VLOOKUP(C9,[1]Sheet!$F:$Q,5,FALSE) -> 377990 | BH9: =VLOOKUP(C9,[1]Sheet!$F:$Q,12,FALSE) -> 0 | BI9: =BG9-BH9 -> 377990
A10: =ROW()-2 -> 8 | C10: CICU1013499 | D10: NSS | E10: Onetouch | F10: Sataka | G10: Sorento | H10: Wenli+Haihuang | J10: 46206 | K10: 46209 | L10: 46211 | M10: 46217 | N10: 46220 | Q10: 14 | R10: + | S10: 7 | X10: 46220 | AH10: 0.6118 | AI10: 12850 | AJ10: 151588.76 | AK10: =AJ10*1.4% -> 2122.2426 | AL10: 46216 | AM10: 9274.19 | AY10: XY 13/07/2026 08:19AM | BA10: =Q10 -> 14 | BB10: =N10+BA10-1 -> 46233 | BC10: =S10 -> 7 | BD10: =AA10+BC10 -> 7 | BF10: =VLOOKUP(C10,[1]Sheet!$F:$Q,9,FALSE) -> 0.6118 | BG10: =VLOOKUP(C10,[1]Sheet!$F:$Q,5,FALSE) -> 48138.47 | BH10: =VLOOKUP(C10,[1]Sheet!$F:$Q,12,FALSE) -> 0 | BI10: =BG10-BH10 -> 48138.47
A11: =ROW()-2 -> 9 | C11: TGBU9807730 | D11: MSC | E11: Onetouch | F11: MPM | G11: Sorento (Mocha) | H11: Affanni+Kaixin+Kailu+Caizhou+Hanshun+IDC+Sannora+Teca+Honor | J11: 46206 | K11: 46210 | L11: 46212 | M11: 46220 | N11: 46225 | Q11: 14 | R11: + | S11: 0 | AI11: 13400 | BA11: =Q11 -> 14 | BB11: =N11+BA11-1 -> 46238 | BC11: =S11 -> 0 | BD11: =AA11+BC11 -> 0 | BF11: =VLOOKUP(C11,[1]Sheet!$F:$Q,9,FALSE) -> 0.6 | BG11: =VLOOKUP(C11,[1]Sheet!$F:$Q,5,FALSE) -> 0 | BH11: =VLOOKUP(C11,[1]Sheet!$F:$Q,12,FALSE) -> 0 | BI11: =BG11-BH11 -> 0
A12: =ROW()-2 -> 10 | C12: TGCU5463218 | D12: CMA | E12: Onetouch | F12: MPM | G12: Sorento (Mocha) | H12: Muchen | J12: 46208 | K12: 46148 | L12: 46211 | M12: 46223 | N12: 46223 | Q12: 14 | R12: + | S12: 0 | AH12: 0.6027 | AI12: 7800 | AJ12: 178325.66 | AK12: =AJ12*1.4 -> 249655.92 | AL12: 46219 | AM12: 10747.7 | AY12: XY 16/07/2026 14:20PM | BA12: =Q12 -> 14 | BB12: =N12+BA12-1 -> 46236 | BC12: =S12 -> 0 | BD12: =AA12+BC12 -> 0 | BF12: =VLOOKUP(C12,[1]Sheet!$F:$Q,9,FALSE) -> 0.6027 | BG12: =VLOOKUP(C12,[1]Sheet!$F:$Q,5,FALSE) -> 70560.98 | BH12: =VLOOKUP(C12,[1]Sheet!$F:$Q,12,FALSE) -> 0 | BI12: =BG12-BH12 -> 70560.98
A13: =ROW()-2 -> 11 | C13: TLLU5104257 | D13: CMA | E13: Onetouch | F13: MPM | G13: Sorento | H13: Muchen | J13: 46208 | K13: 46148 | L13: 46211 | M13: 46223 | N13: 46223 | Q13: 14 | R13: + | S13: 0 | AH13: 0.6027 | AI13: 7800 | AL13: 46219 | AY13: XY 16/07/2026 14:20PM | BA13: =Q13 -> 14 | BB13: =N13+BA13-1 -> 46236 | BC13: =S13 -> 0 | BD13: =AA13+BC13 -> 0 | BF13: =VLOOKUP(C13,[1]Sheet!$F:$Q,9,FALSE) -> 0.6027 | BG13: =VLOOKUP(C13,[1]Sheet!$F:$Q,5,FALSE) -> 92522.48 | BH13: =VLOOKUP(C13,[1]Sheet!$F:$Q,12,FALSE) -> 0 | BI13: =BG13-BH13 -> 92522.48
A14: =ROW()-2 -> 12 | C14: TCNU3108843 | D14: CMA | E14: Hongxin | F14: MPM | G14: Sorento (Mocha) | H14: Taiyang | J14: 46209 | K14: 46210 | L14: 46303 | M14: 46223 | N14: 46223 | Q14: 14 | R14: + | S14: 0 | AH14: 0.6027 | AI14: 11200 | AJ14: 580792.38 | AK14: =AJ14*1.4% -> 8131.0933 | AL14: 46219 | AM14: 32485.1 | AY14: XY 16/07/2026 16:00PM | BA14: =Q14 -> 14 | BB14: =N14+BA14-1 -> 46236 | BC14: =S14 -> 0 | BD14: =AA14+BC14 -> 0 | BF14: =VLOOKUP(C14,[1]Sheet!$F:$Q,9,FALSE) -> #N/A | BG14: =VLOOKUP(C14,[1]Sheet!$F:$Q,5,FALSE) -> #N/A | BH14: =VLOOKUP(C14,[1]Sheet!$F:$Q,12,FALSE) -> #N/A | BI14: =BG14-BH14 -> #N/A
A15: =ROW()-2 -> 13 | C15: MSBU7310757 | D15: MSC | E15: Onetouch | F15: MPM | G15: Sorento | H15: Meisidi | J15: 46215 | K15: 46220 | L15: 46222 | M15: 46228 | N15: 46231 | Q15: 14 | R15: + | S15: 0 | AI15: 12000 | BA15: =Q15 -> 14 | BB15: =N15+BA15-1 -> 46244 | BC15: =S15 -> 0 | BD15: =AA15+BC15 -> 0 | BF15: =VLOOKUP(C15,[1]Sheet!$F:$Q,9,FALSE) -> #N/A | BG15: =VLOOKUP(C15,[1]Sheet!$F:$Q,5,FALSE) -> #N/A | BH15: =VLOOKUP(C15,[1]Sheet!$F:$Q,12,FALSE) -> #N/A | BI15: =BG15-BH15 -> #N/A
A16: =ROW()-2 -> 14 | C16: HASU4622420 | D16: MAE | E16: Onetouch | F16: MPM | G16: Sorento | H16: Muchen (Min Liong Kuching) | J16: 46216 | K16: 46218 | L16: 46220 | M16: 46231 | N16: 46231 | Q16: 14 | R16: + | S16: 0 | AI16: 16700 | BA16: =Q16 -> 14 | BB16: =N16+BA16-1 -> 46244 | BC16: =S16 -> 0 | BD16: =AA16+BC16 -> 0 | BF16: =VLOOKUP(C16,[1]Sheet!$F:$Q,9,FALSE) -> #N/A | BG16: =VLOOKUP(C16,[1]Sheet!$F:$Q,5,FALSE) -> #N/A | BH16: =VLOOKUP(C16,[1]Sheet!$F:$Q,12,FALSE) -> #N/A | BI16: =BG16-BH16 -> #N/A
A17: =ROW()-2 -> 15 | C17: TCLU1848910 | D17: CMA | E17: Onetouch | F17: MPM | G17: Sorento (Mocha) | H17: Wenli | J17: 46217 | K17: 46220 | L17: 46222 | M17: 46230 | Q17: 14 | R17: + | S17: 0 | AI17: 12000 | BA17: =Q17 -> 14 | BB17: =N17+BA17-1 -> 13 | BC17: =S17 -> 0 | BD17: =AA17+BC17 -> 0 | BF17: =VLOOKUP(C17,[1]Sheet!$F:$Q,9,FALSE) -> #N/A | BG17: =VLOOKUP(C17,[1]Sheet!$F:$Q,5,FALSE) -> #N/A | BH17: =VLOOKUP(C17,[1]Sheet!$F:$Q,12,FALSE) -> #N/A | BI17: =BG17-BH17 -> #N/A
A18: =ROW()-2 -> 16 | C18: TCNU5544173 | D18: CMA | E18: Onetouch | F18: MPM | G18: Sorento (Mocha) | H18: Lanyi+Nat Plumbing+Wenli+Haihuang | J18: 46217 | K18: 46221 | L18: 46223 | M18: 46231 | Q18: 14 | R18: + | S18: 0 | AI18: 12100 | BA18: =Q18 -> 14 | BB18: =N18+BA18-1 -> 13 | BC18: =S18 -> 0 | BD18: =AA18+BC18 -> 0 | BF18: =VLOOKUP(C18,[1]Sheet!$F:$Q,9,FALSE) -> #N/A | BG18: =VLOOKUP(C18,[1]Sheet!$F:$Q,5,FALSE) -> #N/A | BH18: =VLOOKUP(C18,[1]Sheet!$F:$Q,12,FALSE) -> #N/A | BI18: =BG18-BH18 -> #N/A
A19: =ROW()-2 -> 17 | C19: BEAU4036375 | D19: CMA | E19: Hongxin | F19: MPM | G19: Sorento (Mocha) | H19: Taiyang | J19: 46219 | K19: 46220 | L19: 46222 | M19: 46230 | Q19: 14 | R19: + | S19: 0 | AI19: 10800 | BA19: =Q19 -> 14 | BB19: =N19+BA19-1 -> 13 | BC19: =S19 -> 0 | BD19: =AA19+BC19 -> 0 | BF19: =VLOOKUP(C19,[1]Sheet!$F:$Q,9,FALSE) -> #N/A | BG19: =VLOOKUP(C19,[1]Sheet!$F:$Q,5,FALSE) -> #N/A | BH19: =VLOOKUP(C19,[1]Sheet!$F:$Q,12,FALSE) -> #N/A | BI19: =BG19-BH19 -> #N/A
A20: =ROW()-2 -> 18 | R20: + | BA20: =Q20 -> 0 | BB20: =N20+BA20-1 -> -1 | BC20: =S20 -> 0 | BD20: =AA20+BC20 -> 0 | BF20: =VLOOKUP(C20,[1]Sheet!$F:$Q,9,FALSE) -> #N/A | BG20: =VLOOKUP(C20,[1]Sheet!$F:$Q,5,FALSE) -> #N/A | BH20: =VLOOKUP(C20,[1]Sheet!$F:$Q,12,FALSE) -> #N/A | BI20: =BG20-BH20 -> #N/A
A21: =ROW()-2 -> 19 | R21: + | BA21: =Q21 -> 0 | BB21: =N21+BA21-1 -> -1 | BC21: =S21 -> 0 | BD21: =AA21+BC21 -> 0 | BF21: =VLOOKUP(C21,[1]Sheet!$F:$Q,9,FALSE) -> #N/A | BG21: =VLOOKUP(C21,[1]Sheet!$F:$Q,5,FALSE) -> #N/A | BH21: =VLOOKUP(C21,[1]Sheet!$F:$Q,12,FALSE) -> #N/A | BI21: =BG21-BH21 -> #N/A
A22: =ROW()-2 -> 20 | R22: + | BA22: =Q22 -> 0 | BB22: =N22+BA22-1 -> -1 | BC22: =S22 -> 0 | BD22: =AA22+BC22 -> 0 | BF22: =VLOOKUP(C22,[1]Sheet!$F:$Q,9,FALSE) -> #N/A | BG22: =VLOOKUP(C22,[1]Sheet!$F:$Q,5,FALSE) -> #N/A | BH22: =VLOOKUP(C22,[1]Sheet!$F:$Q,12,FALSE) -> #N/A | BI22: =BG22-BH22 -> #N/A
A23: =ROW()-2 -> 21 | R23: + | BA23: =Q23 -> 0 | BB23: =N23+BA23-1 -> -1 | BC23: =S23 -> 0 | BD23: =AA23+BC23 -> 0 | BF23: =VLOOKUP(C23,[1]Sheet!$F:$Q,9,FALSE) -> #N/A | BG23: =VLOOKUP(C23,[1]Sheet!$F:$Q,5,FALSE) -> #N/A | BH23: =VLOOKUP(C23,[1]Sheet!$F:$Q,12,FALSE) -> #N/A | BI23: =BG23-BH23 -> #N/A
A24: =ROW()-2 -> 22 | R24: + | BA24: =Q24 -> 0 | BB24: =N24+BA24-1 -> -1 | BC24: =S24 -> 0 | BD24: =AA24+BC24 -> 0 | BF24: =VLOOKUP(C24,[1]Sheet!$F:$Q,9,FALSE) -> #N/A | BG24: =VLOOKUP(C24,[1]Sheet!$F:$Q,5,FALSE) -> #N/A | BH24: =VLOOKUP(C24,[1]Sheet!$F:$Q,12,FALSE) -> #N/A | BI24: =BG24-BH24 -> #N/A
A25: =ROW()-2 -> 23 | R25: + | BA25: =Q25 -> 0 | BB25: =N25+BA25-1 -> -1 | BC25: =S25 -> 0 | BD25: =AA25+BC25 -> 0 | BF25: =VLOOKUP(C25,[1]Sheet!$F:$Q,9,FALSE) -> #N/A | BG25: =VLOOKUP(C25,[1]Sheet!$F:$Q,5,FALSE) -> #N/A | BH25: =VLOOKUP(C25,[1]Sheet!$F:$Q,12,FALSE) -> #N/A | BI25: =BG25-BH25 -> #N/A
A26: =ROW()-2 -> 24 | R26: + | BA26: =Q26 -> 0 | BB26: =N26+BA26-1 -> -1 | BC26: =S26 -> 0 | BD26: =AA26+BC26 -> 0 | BF26: =VLOOKUP(C26,[1]Sheet!$F:$Q,9,FALSE) -> #N/A | BG26: =VLOOKUP(C26,[1]Sheet!$F:$Q,5,FALSE) -> #N/A | BH26: =VLOOKUP(C26,[1]Sheet!$F:$Q,12,FALSE) -> #N/A | BI26: =BG26-BH26 -> #N/A
A27: =ROW()-2 -> 25 | R27: + | BA27: =Q27 -> 0 | BB27: =N27+BA27-1 -> -1 | BC27: =S27 -> 0 | BD27: =AA27+BC27 -> 0 | BF27: =VLOOKUP(C27,[1]Sheet!$F:$Q,9,FALSE) -> #N/A | BG27: =VLOOKUP(C27,[1]Sheet!$F:$Q,5,FALSE) -> #N/A | BH27: =VLOOKUP(C27,[1]Sheet!$F:$Q,12,FALSE) -> #N/A | BI27: =BG27-BH27 -> #N/A
A30: FITTING CONTAINER 2026 (JOINT MOCHA CONTAINER) | AT30: 1.6
A31: NO | B31: LOC | C31: CONTAINER | D31: LINER | E31: CHINA FORWARDER | F31: MALAYSIA FORWARDER | G31: CONSIGNEE | H31: FACTORY | I31: PRODUCT | J31: LOADING | K31: ETC | L31: ETD | M31: ETA | N31: ETA DELAY | O31: ATA | P31: STACKED | Q31: FREE DAYS AVAILABLE | T31: INSPECTION | U31: APPROVAL | V31: ORI DOC RECEIVED DATE | W31: K1 SUBMISSION | X31: GATEPASS | Y31: DELIVERY WAREHOUSE | Z31: YARD ARRIVALS | AA31: WAREHOUSE ARRIVALS | AB31: INFORMED COLLECTION | AC31: COLLECTION | AD31: REMARKS 1 | AE31: REMARKS 2 | AF31: REMARKS 3 | AG31: 2ND LABOUR CHARGE | AH31: K1 RATE | AI31: CHINA FORWARDING COST (RMB) | AL31: DATE RECEIVE K1 | AM31: SST AMOUNT | AN31: LOCAL CLEARANCE CHARGES | AO31: KOPI | AP31: DEMURRAGE | AQ31: PORT CHARGES | AR31: DETENTION | AS31: TOTAL LOCAL CLEARANCE | AT31: TOTAL FREIGHT | AU31: CARGO INSURANCE | AV31: SRT? MBS? BOTH? | AW31: LOCAL CLEARANCE CHARGES | AX31: USD | AY31: 10% SST | BB31: Demurrange | BD31: Detention
A32: 1 | C32: GXYU5109142 | D32: CMA | E32: Onetouch | F32: MPM | G32: Mocha | H32: Teca | J32: 46182 | K32: 46186 | L32: 46188 | M32: 46194 | N32: 46215 | Q32: 21 | R32: + | S32: 0 | X32: 46221 | AI32: 12450 | BA32: =Q32 -> 21 | BB32: =N32+BA32-1 -> 46235 | BC32: =S32 -> 0 | BD32: =AA32+BC32 -> 0 | BF32: =VLOOKUP(C32,[1]Sheet!$F:$Q,9,FALSE) -> 0.6118 | BG32: =VLOOKUP(C32,[1]Sheet!$F:$Q,5,FALSE) -> 0 | BH32: =VLOOKUP(C32,[1]Sheet!$F:$Q,12,FALSE) -> 0 | BI32: =BG32-BH32 -> 0
A33: ='Arrived - Joint Mocha Container'!A17+1 -> 5 | C33: GESU6719892 | D33: CMA | E33: Onetouch | F33: MPM | G33: Mocha | H33: Haihuang | J33: 46214 | K33: 46217 | L33: 46219 | M33: 46227 | N33: 46232 | Q33: 14 | S33: 0 | AI33: 12000 | BA33: =Q33 -> 14 | BB33: =N33+BA33-1 -> 46245 | BC33: =S33 -> 0 | BD33: =AA33+BC33 -> 0 | BF33: =VLOOKUP(C33,[1]Sheet!$F:$Q,9,FALSE) -> #N/A | BG33: =VLOOKUP(C33,[1]Sheet!$F:$Q,5,FALSE) -> #N/A | BH33: =VLOOKUP(C33,[1]Sheet!$F:$Q,12,FALSE) -> #N/A | BI33: =BG33-BH33 -> #N/A
A34: =A33+1 -> 6 | BA34: =Q34 -> 0 | BB34: =N34+BA34-1 -> -1 | BC34: =S34 -> 0 | BD34: =AA34+BC34 -> 0 | BF34: =VLOOKUP(C34,[1]Sheet!$F:$Q,9,FALSE) -> #N/A | BG34: =VLOOKUP(C34,[1]Sheet!$F:$Q,5,FALSE) -> #N/A | BH34: =VLOOKUP(C34,[1]Sheet!$F:$Q,12,FALSE) -> #N/A | BI34: =BG34-BH34 -> #N/A
A35: =A34+1 -> 7 | BA35: =Q35 -> 0 | BB35: =N35+BA35-1 -> -1 | BC35: =S35 -> 0 | BD35: =AA35+BC35 -> 0 | BF35: =VLOOKUP(C35,[1]Sheet!$F:$Q,9,FALSE) -> #N/A | BG35: =VLOOKUP(C35,[1]Sheet!$F:$Q,5,FALSE) -> #N/A | BH35: =VLOOKUP(C35,[1]Sheet!$F:$Q,12,FALSE) -> #N/A | BI35: =BG35-BH35 -> #N/A

Sheet Ceramic
A1: CERAMIC CONTAINER 2026 | AT1: 1.6
A2: NO | B2: LOC | C2: CONTAINER | D2: RL | E2: CHINA FORWARDER | F2: MALAYSIA FORWARDER | G2: CONSIGNEE | H2: FACTORY | I2: PRODUCT | J2: LOADING | K2: ETC | L2: ETD | M2: ETA | N2: ETA DELAY | O2: ATA | P2: STACKED | Q2: FREE DAYS AVAILABLE | T2: INSPECTION | U2: APPROVAL | V2: ORI DOC RECEIVED DATE | W2: K1 SUBMISSION | X2: GATEPASS | Y2: DELIVERY WAREHOUSE | Z2: YARD ARRIVALS | AA2: WAREHOUSE ARRIVALS | AB2: INFORMED COLLECTION | AC2: COLLECTION | AD2: REMARKS 1 | AE2: REMARKS 2 | AF2: REMARKS 3 | AG2: 2ND LABOUR CHARGE | AH2: K1 RATE | AI2: CHINA FORWARDING COST (RMB) | AJ2: PRODUCT VALUE (RMB) | AK2: 0.014 | AL2: DATE RECEIVE K1 | AM2: SST AMOUNT | AN2: LOCAL CLEARANCE CHARGES | AO2: KOPI | AP2: DEMURRAGE | AQ2: PORT CHARGES | AR2: DETENTION | AS2: TOTAL LOCAL CLEARANCE | AT2: TOTAL FREIGHT | AU2: CARGO INSURANCE | AV2: SRT? MBS? BOTH? | AW2: LOCAL CLEARANCE CHARGES | AX2: USD | AY2: SST | BB2: Demurrage | BD2: Detention | BF2: Rate | BG2: System | BH2: Actual | BI2: Diff
A3: =ROW()-2 -> 1 | C3: HPCU5036948 | D3: SITC | E3: J&H | F3: MPM | G3: Sorento | H3: Jiexia+Lanyi+Dafuyuan+Jinbaichuan+Gaode | J3: 46188 | K3: 46193 | L3: 46195 | M3: 46203 | N3: 46204 | Q3: 14 | R3: + | S3: 5 | T3: 46209 | U3: 46212 | AH3: 0.6059 | AI3: 26800 | AJ3: 99630.001 | AK3: =AJ3*1.4% -> 1394.82 | AL3: 46202 | AM3: =94.95+5846.65 -> 5941.6 | AY3: XY 29/06/2026 13:25PM | BA3: =Q3 -> 14 | BB3: =N3+BA3-1 -> 46217 | BC3: =S3 -> 5 | BD3: =AA3+BC3 -> 5 | BF3: =VLOOKUP(C3,[1]Sheet!$F:$Q,9,FALSE) -> #N/A | BG3: =VLOOKUP(C3,[1]Sheet!$F:$Q,5,FALSE) -> #N/A | BH3: =VLOOKUP(C3,[1]Sheet!$F:$Q,12,FALSE) -> #N/A | BI3: =BG3-BH3 -> #N/A
A4: =ROW()-2 -> 2 | B4: BRW | C4: FCIU7600305 | D4: CMA | E4: Haiian | F4: Haiian | G4: Sorento | H4: Jinbaichuan | I4: 8354-SH-200+8354-SH+8354-SH-P+83154-SH-150 | J4: 46193 | K4: 46196 | L4: 46198 | M4: 46207 | N4: 46208 | Q4: 21 | R4: + | S4: 0 | T4: 46212 | U4: 46213 | X4: 46218 | AI4: 10300 | AJ4: 123760 | AK4: =AJ4*1.4% -> 1732.64 | AY4: XY 30/06/2026 05.05.PM | BA4: =Q4 -> 21 | BB4: =N4+BA4-1 -> 46228 | BC4: =S4 -> 0 | BD4: =AA4+BC4 -> 0 | BF4: =VLOOKUP(C4,[1]Sheet!$F:$Q,9,FALSE) -> 0.6118 | BG4: =VLOOKUP(C4,[1]Sheet!$F:$Q,5,FALSE) -> 123760 | BH4: =VLOOKUP(C4,[1]Sheet!$F:$Q,12,FALSE) -> 0 | BI4: =BG4-BH4 -> 123760
A5: =ROW()-2 -> 3 | B5: DC1 | C5: SEGU4326041 | D5: CMA | E5: Haiian | F5: Haiian | G5: Sorento | H5: Jinbaichuan | I5: 8152-SH+8152-SH-300 | J5: 46193 | K5: 46196 | L5: 46198 | M5: 46207 | N5: 46208 | Q5: 21 | R5: + | S5: 0 | T5: 46212 | U5: 46213 | X5: 46218 | AI5: 10300 | AJ5: 109040 | AK5: =AJ5*1.4% -> 1526.56 | AY5: XY 30/06/2026 05.05.PM | BA5: =Q5 -> 21 | BB5: =N5+BA5-1 -> 46228 | BC5: =S5 -> 0 | BD5: =AA5+BC5 -> 0 | BF5: =VLOOKUP(C5,[1]Sheet!$F:$Q,9,FALSE) -> 0.6118 | BG5: =VLOOKUP(C5,[1]Sheet!$F:$Q,5,FALSE) -> 109040 | BH5: =VLOOKUP(C5,[1]Sheet!$F:$Q,12,FALSE) -> 0 | BI5: =BG5-BH5 -> 109040
A6: =ROW()-2 -> 4 | B6: DC1 | C6: CAIU7321914 | D6: CMA | E6: Haiian | F6: Haiian | G6: Sorento | H6: Jinbaichuan | I6: CWC7606-SH-P+CWC7606-SH+CWC8154-RL | J6: 46193 | K6: 46196 | L6: 46198 | M6: 46207 | N6: 46208 | Q6: 21 | R6: + | S6: 0 | T6: 46212 | U6: 46213 | X6: 46218 | AI6: 10300 | AJ6: 91840 | AK6: =AJ6*1.4% -> 1285.76 | AY6: XY 30/06/2026 05.05.PM | BA6: =Q6 -> 21 | BB6: =N6+BA6-1 -> 46228 | BC6: =S6 -> 0 | BD6: =AA6+BC6 -> 0 | BF6: =VLOOKUP(C6,[1]Sheet!$F:$Q,9,FALSE) -> 0.6118 | BG6: =VLOOKUP(C6,[1]Sheet!$F:$Q,5,FALSE) -> 91840 | BH6: =VLOOKUP(C6,[1]Sheet!$F:$Q,12,FALSE) -> 0 | BI6: =BG6-BH6 -> 91840
A7: =ROW()-2 -> 5 | C7: CAIU9302087 | D7: CMA | E7: Haiian | F7: Haiian | G7: Sorento (Mocha) | H7: Jinbaichuan | I7: 8354-SH+287-RL-P+287-RL+287A-RL+8154-RL+7606-SH+MWCSC8606+7405-RL | J7: 46193 | K7: 46196 | L7: 46198 | M7: 46207 | N7: 46208 | Q7: 21 | R7: + | S7: 0 | T7: 46212 | U7: 46213 | X7: 46218 | AI7: 10300 | AJ7: 119310 | AK7: =AJ7*1.4% -> 1670.34 | AY7: XY 30/06/2026 05.05.PM | BA7: =Q7 -> 21 | BB7: =N7+BA7-1 -> 46228 | BC7: =S7 -> 0 | BD7: =AA7+BC7 -> 0 | BF7: =VLOOKUP(C7,[1]Sheet!$F:$Q,9,FALSE) -> 0.6118 | BG7: =VLOOKUP(C7,[1]Sheet!$F:$Q,5,FALSE) -> 107530 | BH7: =VLOOKUP(C7,[1]Sheet!$F:$Q,12,FALSE) -> 0 | BI7: =BG7-BH7 -> 107530
A8: =ROW()-2 -> 6 | C8: SEKU5746315 | D8: CMA | E8: Haiian | F8: Haiian | G8: Sorento (Mocha) | H8: Jinbaichuan | I8: MWC7625-SH-S10+7601-RL+286-SH-NEW | J8: 46193 | K8: 46196 | L8: 46198 | M8: 46207 | N8: 46208 | Q8: 21 | R8: + | S8: 0 | T8: 46212 | U8: 46213 | X8: 46218 | AI8: 10300 | AJ8: 104964 | AK8: =AJ8*1.4% -> 1469.496 | AY8: XY 30/06/2026 05.05.PM | BA8: =Q8 -> 21 | BB8: =N8+BA8-1 -> 46228 | BC8: =S8 -> 0 | BD8: =AA8+BC8 -> 0 | BF8: =VLOOKUP(C8,[1]Sheet!$F:$Q,9,FALSE) -> 0.6118 | BG8: =VLOOKUP(C8,[1]Sheet!$F:$Q,5,FALSE) -> 66700 | BH8: =VLOOKUP(C8,[1]Sheet!$F:$Q,12,FALSE) -> 0 | BI8: =BG8-BH8 -> 66700
A9: =ROW()-2 -> 7 | B9: DC1 | C9: ECMU5211493 | D9: CMA | E9: Haiian | F9: Haiian | G9: Sorento | H9: Jinbaichuan | I9: 243+605-RL+241 | J9: 46193 | K9: 46196 | L9: 46198 | M9: 46207 | N9: 46208 | Q9: 21 | R9: + | S9: 0 | T9: 46212 | U9: 46213 | X9: 46218 | AI9: 10300 | AJ9: 95838 | AK9: =AJ9*1.4% -> 1341.732 | AY9: XY 30/06/2026 05.05.PM | BA9: =Q9 -> 21 | BB9: =N9+BA9-1 -> 46228 | BC9: =S9 -> 0 | BD9: =AA9+BC9 -> 0 | BF9: =VLOOKUP(C9,[1]Sheet!$F:$Q,9,FALSE) -> 0.6118 | BG9: =VLOOKUP(C9,[1]Sheet!$F:$Q,5,FALSE) -> 95838 | BH9: =VLOOKUP(C9,[1]Sheet!$F:$Q,12,FALSE) -> 0 | BI9: =BG9-BH9 -> 95838
A10: =ROW()-2 -> 8 | C10: TGBU6830910 | D10: CMA | E10: Haiian | F10: Haiian | G10: Sorento | H10: Jinbaichuan | I10: CWC242+242+247+CWB247+762+890+243+3412-GY+Laser Printing Machine | J10: 46193 | K10: 46196 | L10: 46198 | M10: 46207 | N10: 46208 | Q10: 21 | R10: + | S10: 0 | T10: 46212 | U10: 46213 | X10: 46218 | AI10: 10300 | AJ10: 122334.5 | AK10: =AJ10*1.4% -> 1712.683 | AY10: XY 30/06/2026 05.05.PM | BA10: =Q10 -> 21 | BB10: =N10+BA10-1 -> 46228 | BC10: =S10 -> 0 | BD10: =AA10+BC10 -> 0 | BF10: =VLOOKUP(C10,[1]Sheet!$F:$Q,9,FALSE) -> 0.6118 | BG10: =VLOOKUP(C10,[1]Sheet!$F:$Q,5,FALSE) -> 122334.5 | BH10: =VLOOKUP(C10,[1]Sheet!$F:$Q,12,FALSE) -> 0 | BI10: =BG10-BH10 -> 122334.5
A11: =ROW()-2 -> 9 | B11: BRW | C11: APHU7194711 | D11: CMA | E11: Haiian | F11: Haiian | G11: Sorento | H11: Jiohol | I11: CWC7601-S-ECO | J11: 46194 | K11: 46196 | L11: 46198 | M11: 46207 | N11: 46208 | Q11: 21 | R11: + | S11: 0 | T11: 46211 | U11: 46212 | X11: 46217 | AH11: 0.6031 | AI11: 10700 | AJ11: 69888 | AK11: =AJ11*1.4% -> 978.432 | AL11: 46199 | AM11: 13990.75 | AY11: XY 26/06/2026 09:07AM | BA11: =Q11 -> 21 | BB11: =N11+BA11-1 -> 46228 | BC11: =S11 -> 0 | BD11: =AA11+BC11 -> 0 | BF11: =VLOOKUP(C11,[1]Sheet!$F:$Q,9,FALSE) -> 0.6118 | BG11: =VLOOKUP(C11,[1]Sheet!$F:$Q,5,FALSE) -> 69888 | BH11: =VLOOKUP(C11,[1]Sheet!$F:$Q,12,FALSE) -> 0 | BI11: =BG11-BH11 -> 69888
A12: =ROW()-2 -> 10 | B12: BRW | C12: BEAU4050774 | D12: CMA | E12: Haiian | F12: Haiian | G12: Sorento (Mocha) | H12: Gaode | I12: IBWC78315-S10+IBWC7601-RL-S10+MWC7632-SH-UF-S10+CWC7601-S-RL+CWB1218-N+MAB7043 | J12: 46194 | K12: 46196 | L12: 46198 | M12: 46207 | N12: 46208 | Q12: 21 | R12: + | S12: 0 | T12: 46211 | U12: 46212 | X12: 46217 | AH12: 0.6031 | AI12: 10700 | AJ12: 92205 | AK12: =AJ12*1.4% -> 1290.87 | AL12: 46199 | AM12: 13990.75 | AY12: XY 26/06/2026 09:07AM | BA12: =Q12 -> 21 | BB12: =N12+BA12-1 -> 46228 | BC12: =S12 -> 0 | BD12: =AA12+BC12 -> 0 | BF12: =VLOOKUP(C12,[1]Sheet!$F:$Q,9,FALSE) -> 0.6118 | BG12: =VLOOKUP(C12,[1]Sheet!$F:$Q,5,FALSE) -> 35260 | BH12: =VLOOKUP(C12,[1]Sheet!$F:$Q,12,FALSE) -> 0 | BI12: =BG12-BH12 -> 35260
A13: =ROW()-2 -> 11 | C13: CAAU5977454 | D13: CMA | E13: Haiian | F13: Haiian | G13: Sorento (Full Mocha) | H13: Lanyi | I13: MWC7630-SH-10+7630-SH-S6+7630-SH-S8+7022+700-MG+7024+7044-WH+7045-GY+7045-RG+7045+7046-BL+7046-WH+7049-WH+7050-WH+7626-BL+7626 | J13: 46194 | K13: 46196 | L13: 46198 | M13: 46207 | N13: 46208 | Q13: 21 | R13: + | S13: 0 | T13: 46212 | U13: 46212 | X13: 46217 | AI13: 10700 | AJ13: 119305 | AK13: =AJ13*1.4% -> 1670.27 | AY13: XY 26/06/2026 10.41AM | BA13: =Q13 -> 21 | BB13: =N13+BA13-1 -> 46228 | BC13: =S13 -> 0 | BD13: =AA13+BC13 -> 0 | BF13: =VLOOKUP(C13,[1]Sheet!$F:$Q,9,FALSE) -> #N/A | BG13: =VLOOKUP(C13,[1]Sheet!$F:$Q,5,FALSE) -> #N/A | BH13: =VLOOKUP(C13,[1]Sheet!$F:$Q,12,FALSE) -> #N/A | BI13: =BG13-BH13 -> #N/A
A14: =ROW()-2 -> 12 | C14: EITU9262350 | D14: EMC | E14: Kaidila | F14: MPM | G14: Sorento | H14: Dafuyuan | I14: 888-NEW+8613-RL+8608-RL+8317-RL-WEPLS | J14: 46197 | K14: 46201 | L14: 46204 | M14: 46212 | N14: 46224 | Q14: 14 | R14: + | S14: 7 | T14: 46226 | AI14: 11000 | AJ14: 115110 | AK14: =AJ14*1.4% -> 1611.54 | AY14: XY 20/07/2026 2.29PM | BA14: =Q14 -> 14 | BB14: =N14+BA14-1 -> 46237 | BC14: =S14 -> 7 | BD14: =AA14+BC14 -> 7 | BF14: =VLOOKUP(C14,[1]Sheet!$F:$Q,9,FALSE) -> #N/A | BG14: =VLOOKUP(C14,[1]Sheet!$F:$Q,5,FALSE) -> #N/A | BH14: =VLOOKUP(C14,[1]Sheet!$F:$Q,12,FALSE) -> #N/A | BI14: =BG14-BH14 -> #N/A
A15: =ROW()-2 -> 13 | C15: EGSU1771170 | D15: EMC | E15: Kaidila | F15: MPM | G15: Sorento | H15: Dafuyuan | I15: 8605-RL+8334+5300+5400+7049+7055+1515+7099+6201+8066-S150+8066-S200+8319-P-RL-UF+8318-RL-S200+S/P MUB6201 | J15: 46197 | K15: 46201 | L15: 46204 | M15: 46212 | N15: 46224 | Q15: 14 | R15: + | S15: 7 | T15: 46226 | AI15: 11000 | AJ15: 132002 | AK15: =AJ15*1.4% -> 1848.028 | AY15: XY 20/07/2026 2.29PM | BA15: =Q15 -> 14 | BB15: =N15+BA15-1 -> 46237 | BC15: =S15 -> 7 | BD15: =AA15+BC15 -> 7 | BF15: =VLOOKUP(C15,[1]Sheet!$F:$Q,9,FALSE) -> #N/A | BG15: =VLOOKUP(C15,[1]Sheet!$F:$Q,5,FALSE) -> #N/A | BH15: =VLOOKUP(C15,[1]Sheet!$F:$Q,12,FALSE) -> #N/A | BI15: =BG15-BH15 -> #N/A
A16: =ROW()-2 -> 14 | C16: EMCU1568857 | D16: EMC | E16: Kaidila | F16: MPM | G16: Sorento | H16: Dafuyuan | I16: 7604-S-RL-WEPLS+7604-RL-NEW+8605-RL | J16: 46197 | K16: 46201 | L16: 46204 | M16: 46212 | N16: 46224 | Q16: 14 | R16: + | S16: 7 | T16: 46226 | AI16: 11000 | AJ16: 112346 | AK16: =AJ16*1.4% -> 1572.844 | AY16: XY 20/07/2026 2.29PM | BA16: =Q16 -> 14 | BB16: =N16+BA16-1 -> 46237 | BC16: =S16 -> 7 | BD16: =AA16+BC16 -> 7 | BF16: =VLOOKUP(C16,[1]Sheet!$F:$Q,9,FALSE) -> #N/A | BG16: =VLOOKUP(C16,[1]Sheet!$F:$Q,5,FALSE) -> #N/A | BH16: =VLOOKUP(C16,[1]Sheet!$F:$Q,12,FALSE) -> #N/A | BI16: =BG16-BH16 -> #N/A
A17: =ROW()-2 -> 15 | C17: BMOU6498042 | D17: WHL | E17: Haiian | F17: Haiian | G17: Sorento | H17: Dafuyuan | I17: 7604-S-RL-WEPLS+8605-RL+8318-RL-S200-N+8318-RL-N | J17: 46198 | K17: 46199 | L17: 46201 | M17: 46207 | N17: 46210 | Q17: 14 | R17: + | S17: 7 | T17: 46210 | U17: 46217 | X17: 46219 | AI17: 10700 | AJ17: 105497 | AK17: =AJ17*1.4% -> 1476.958 | AY17: XY 01/07/2026 1.47PM | BA17: =Q17 -> 14 | BB17: =N17+BA17-1 -> 46223 | BC17: =S17 -> 7 | BD17: =AA17+BC17 -> 7 | BF17: =VLOOKUP(C17,[1]Sheet!$F:$Q,9,FALSE) -> 0.6027 | BG17: =VLOOKUP(C17,[1]Sheet!$F:$Q,5,FALSE) -> 105497 | BH17: =VLOOKUP(C17,[1]Sheet!$F:$Q,12,FALSE) -> 0 | BI17: =BG17-BH17 -> 105497
A18: =ROW()-2 -> 16 | B18: BRW | C18: BMOU6495378 | D18: WHL | E18: Haiian | F18: Haiian | G18: Sorento | H18: Dafuyuan | I18: 604-S-RL-NEW+7604-RL-NEW | J18: 46198 | K18: 46199 | L18: 46201 | M18: 46207 | N18: 46210 | Q18: 14 | R18: + | S18: 7 | T18: 46210 | U18: 46217 | X18: 46219 | AI18: 10700 | AJ18: 113354 | AK18: =AJ18*1.4% -> 1586.956 | AY18: XY 01/07/2026 1.47PM | BA18: =Q18 -> 14 | BB18: =N18+BA18-1 -> 46223 | BC18: =S18 -> 7 | BD18: =AA18+BC18 -> 7 | BF18: =VLOOKUP(C18,[1]Sheet!$F:$Q,9,FALSE) -> 0.6027 | BG18: =VLOOKUP(C18,[1]Sheet!$F:$Q,5,FALSE) -> 113354 | BH18: =VLOOKUP(C18,[1]Sheet!$F:$Q,12,FALSE) -> 0 | BI18: =BG18-BH18 -> 113354
A19: =ROW()-2 -> 17 | C19: ONEU5507139 | D19: ONE | E19: J&H | F19: MPM | G19: Sorento (Mocha) | H19: Jiexia | I19: 8826-S-RL+80858-S-UF-RL+MWC7623-SH-S6 | J19: 46199 | K19: 46200 | L19: 46202 | M19: 46210 | N19: 46214 | Q19: 14 | R19: + | S19: 7 | T19: 46217 | U19: 46219 | AI19: 11400 | AJ19: 129484 | AK19: =AJ19*1.4% -> 1812.776 | AY19: XY 1707/2026 04.31PM | BA19: =Q19 -> 14 | BB19: =N19+BA19-1 -> 46227 | BC19: =S19 -> 7 | BD19: =AA19+BC19 -> 7 | BF19: =VLOOKUP(C19,[1]Sheet!$F:$Q,9,FALSE) -> #N/A | BG19: =VLOOKUP(C19,[1]Sheet!$F:$Q,5,FALSE) -> #N/A | BH19: =VLOOKUP(C19,[1]Sheet!$F:$Q,12,FALSE) -> #N/A | BI19: =BG19-BH19 -> #N/A
A20: =ROW()-2 -> 18 | C20: DFSU7655240 | D20: ONE | E20: J&H | F20: MPM | G20: Sorento | H20: Jiexia | I20: 8840-S-RL | J20: 46199 | K20: 46200 | L20: 46202 | M20: 46210 | N20: 46214 | Q20: 14 | R20: + | S20: 7 | T20: 46217 | U20: 46219 | AI20: 11400 | AJ20: 124497 | AK20: =AJ20*1.4% -> 1742.958 | AY20: XY 1707/2026 04.31PM | BA20: =Q20 -> 14 | BB20: =N20+BA20-1 -> 46227 | BC20: =S20 -> 7 | BD20: =AA20+BC20 -> 7 | BF20: =VLOOKUP(C20,[1]Sheet!$F:$Q,9,FALSE) -> #N/A | BG20: =VLOOKUP(C20,[1]Sheet!$F:$Q,5,FALSE) -> #N/A | BH20: =VLOOKUP(C20,[1]Sheet!$F:$Q,12,FALSE) -> #N/A | BI20: =BG20-BH20 -> #N/A
A21: =ROW()-2 -> 19 | C21: ONEU0978795 | D21: ONE | E21: J&H | F21: MPM | G21: Sorento | H21: Jiexia | I21: 8840-S-RL | J21: 46199 | K21: 46200 | L21: 46202 | M21: 46210 | N21: 46214 | Q21: 14 | R21: + | S21: 7 | T21: 46217 | U21: 46219 | AI21: 11400 | AJ21: 124497 | AK21: =AJ21*1.4% -> 1742.958 | AY21: XY 1707/2026 04.31PM | BA21: =Q21 -> 14 | BB21: =N21+BA21-1 -> 46227 | BC21: =S21 -> 7 | BD21: =AA21+BC21 -> 7 | BF21: =VLOOKUP(C21,[1]Sheet!$F:$Q,9,FALSE) -> #N/A | BG21: =VLOOKUP(C21,[1]Sheet!$F:$Q,5,FALSE) -> #N/A | BH21: =VLOOKUP(C21,[1]Sheet!$F:$Q,12,FALSE) -> #N/A | BI21: =BG21-BH21 -> #N/A
A22: =ROW()-2 -> 20 | C22: HPCU2811466 | D22: SITC | E22: J&H | F22: MPM | G22: Sorento | H22: Jinbaichuan+Lanyi+Dafuyuan (MJC Kuching) - 20ft | J22: 46202 | K22: 46145 | L22: 46208 | M22: 46216 | N22: 46216 | Q22: 14 | R22: + | S22: 5 | T22: 46223 | AH22: 0.6027 | AI22: 19600 | AJ22: 47010 | AK22: =AJ22*1.4% -> 658.14 | AL22: 46212 | AM22: =46359.5+650.5 -> 47010 | AY22: XY 09/07/2026 17:44PM | BA22: =Q22 -> 14 | BB22: =N22+BA22-1 -> 46229 | BC22: =S22 -> 5 | BD22: =AA22+BC22 -> 5 | BF22: =VLOOKUP(C22,[1]Sheet!$F:$Q,9,FALSE) -> #N/A | BG22: =VLOOKUP(C22,[1]Sheet!$F:$Q,5,FALSE) -> #N/A | BH22: =VLOOKUP(C22,[1]Sheet!$F:$Q,12,FALSE) -> #N/A | BI22: =BG22-BH22 -> #N/A
A23: =ROW()-2 -> 21 | C23: HPCU4954553 | D23: SITC | E23: Kaidila | F23: MPM | G23: Sorento | H23: Jinbaichuan+Lanyi+Gaode (Kuching) | J23: 46202 | K23: 46145 | L23: 46208 | M23: 46216 | N23: 46216 | Q23: 14 | R23: + | S23: 5 | T23: 46223 | AH23: 0.6118 | AI23: 28350 | AJ23: 94777 | AK23: =AJ23*1.4% -> 1326.878 | AL23: 46212 | AM23: =89120+3460.95 -> 92580.95 | AY23: XY 09/07/2026 17:44PM | BA23: =Q23 -> 14 | BB23: =N23+BA23-1 -> 46229 | BC23: =S23 -> 5 | BD23: =AA23+BC23 -> 5 | BF23: =VLOOKUP(C23,[1]Sheet!$F:$Q,9,FALSE) -> #N/A | BG23: =VLOOKUP(C23,[1]Sheet!$F:$Q,5,FALSE) -> #N/A | BH23: =VLOOKUP(C23,[1]Sheet!$F:$Q,12,FALSE) -> #N/A | BI23: =BG23-BH23 -> #N/A
A24: =ROW()-2 -> 22 | C24: YMLU5711160 | D24: YML | E24: MPM | F24: MPM | G24: Sorento | H24: Bravat | J24: 46206 | K24: 46209 | L24: 46211 | M24: 46218 | N24: 46223 | Q24: 14 | R24: + | S24: 7 | T24: 46223 | AK24: =AJ24*1.4% -> 0 | BA24: =Q24 -> 14 | BB24: =N24+BA24-1 -> 46236 | BC24: =S24 -> 7 | BD24: =AA24+BC24 -> 7 | BF24: =VLOOKUP(C24,[1]Sheet!$F:$Q,9,FALSE) -> #N/A | BG24: =VLOOKUP(C24,[1]Sheet!$F:$Q,5,FALSE) -> #N/A | BH24: =VLOOKUP(C24,[1]Sheet!$F:$Q,12,FALSE) -> #N/A | BI24: =BG24-BH24 -> #N/A
A25: =ROW()-2 -> 23 | C25: YMMU4005991 | D25: YML | E25: MPM | F25: MPM | G25: Sorento | H25: Bravat | J25: 46206 | K25: 46209 | L25: 46211 | M25: 46218 | N25: 46223 | Q25: 14 | R25: + | S25: 7 | T25: 46223 | AK25: =AJ25*1.4% -> 0 | BA25: =Q25 -> 14 | BB25: =N25+BA25-1 -> 46236 | BC25: =S25 -> 7 | BD25: =AA25+BC25 -> 7 | BF25: =VLOOKUP(C25,[1]Sheet!$F:$Q,9,FALSE) -> #N/A | BG25: =VLOOKUP(C25,[1]Sheet!$F:$Q,5,FALSE) -> #N/A | BH25: =VLOOKUP(C25,[1]Sheet!$F:$Q,12,FALSE) -> #N/A | BI25: =BG25-BH25 -> #N/A
A26: =ROW()-2 -> 24 | C26: WHLU5826980 | D26: WHL | E26: Kaidila | F26: MPM | G26: Sorento (Full Mocha) | H26: Jiohol | I26: IBWC7601-ECO-S10+SAMPLE BASIN | J26: 46208 | K26: 46149 | L26: 46213 | M26: 46221 | N26: 46224 | Q26: 14 | R26: + | S26: 7 | AI26: 11400 | AK26: =AJ26*1.4% -> 0 | AY26: XY 20/07/2026 02.28PM | BA26: =Q26 -> 14 | BB26: =N26+BA26-1 -> 46237 | BC26: =S26 -> 7 | BD26: =AA26+BC26 -> 7 | BF26: =VLOOKUP(C26,[1]Sheet!$F:$Q,9,FALSE) -> #N/A | BG26: =VLOOKUP(C26,[1]Sheet!$F:$Q,5,FALSE) -> #N/A | BH26: =VLOOKUP(C26,[1]Sheet!$F:$Q,12,FALSE) -> #N/A | BI26: =BG26-BH26 -> #N/A
A27: =ROW()-2 -> 25 | C27: WHSU5295488 | D27: WHL | E27: Kaidila | F27: MPM | G27: Sorento (Full Mocha) | H27: Jiohol | I27: IBWC7601-ECO-S10+IBWC7632-SH-UF-S10 | J27: 46208 | K27: 46149 | L27: 46213 | M27: 46221 | N27: 46224 | Q27: 14 | R27: + | S27: 7 | AI27: 11400 | AK27: =AJ27*1.4% -> 0 | AY27: XY 20/07/2026 02.28PM | BA27: =Q27 -> 14 | BB27: =N27+BA27-1 -> 46237 | BC27: =S27 -> 7 | BD27: =AA27+BC27 -> 7 | BF27: =VLOOKUP(C27,[1]Sheet!$F:$Q,9,FALSE) -> #N/A | BG27: =VLOOKUP(C27,[1]Sheet!$F:$Q,5,FALSE) -> #N/A | BH27: =VLOOKUP(C27,[1]Sheet!$F:$Q,12,FALSE) -> #N/A | BI27: =BG27-BH27 -> #N/A
A28: =ROW()-2 -> 26 | C28: CAIU7857234 | D28: WHL | E28: Kaidila | F28: MPM | G28: Sorento (Mocha) | H28: Gaode | I28: IBWC7601-RL-S10+CWC7601-S-RL+CWC8315-NEW | J28: 46208 | K28: 46149 | L28: 46213 | M28: 46221 | N28: 46224 | Q28: 14 | R28: + | S28: 7 | AI28: 11400 | AK28: =AJ28*1.4% -> 0 | AY28: XY 20/07/2026 02.28PM | BA28: =Q28 -> 14 | BB28: =N28+BA28-1 -> 46237 | BC28: =S28 -> 7 | BD28: =AA28+BC28 -> 7 | BF28: =VLOOKUP(C28,[1]Sheet!$F:$Q,9,FALSE) -> #N/A | BG28: =VLOOKUP(C28,[1]Sheet!$F:$Q,5,FALSE) -> #N/A | BH28: =VLOOKUP(C28,[1]Sheet!$F:$Q,12,FALSE) -> #N/A | BI28: =BG28-BH28 -> #N/A
A29: =ROW()-2 -> 27 | C29: GCXU6244964 | D29: WHL | E29: J&H | F29: MPM | G29: Sorento (Full Mocha) | H29: Jiohol | I29: IBWC7601-EXO-S10 | J29: 46208 | K29: 46149 | L29: 46213 | M29: 46221 | N29: 46225 | Q29: 14 | R29: + | S29: 7 | T29: 46226 | AI29: 11700 | AK29: =AJ29*1.4% -> 0 | AY29: XY 20/07/2026 2.32PM | BA29: =Q29 -> 14 | BB29: =N29+BA29-1 -> 46238 | BC29: =S29 -> 7 | BD29: =AA29+BC29 -> 7 | BF29: =VLOOKUP(C29,[1]Sheet!$F:$Q,9,FALSE) -> #N/A | BG29: =VLOOKUP(C29,[1]Sheet!$F:$Q,5,FALSE) -> #N/A | BH29: =VLOOKUP(C29,[1]Sheet!$F:$Q,12,FALSE) -> #N/A | BI29: =BG29-BH29 -> #N/A
A30: =ROW()-2 -> 28 | C30: WHSU8449801 | D30: WHL | E30: J&H | F30: MPM | G30: Sorento | H30: Jiohol | I30: CWC7601-S-ECO | J30: 46208 | K30: 46149 | L30: 46213 | M30: 46221 | N30: 46225 | Q30: 14 | R30: + | S30: 7 | T30: 46226 | AI30: 11700 | AK30: =AJ30*1.4% -> 0 | AY30: XY 20/07/2026 2.32PM | BA30: =Q30 -> 14 | BB30: =N30+BA30-1 -> 46238 | BC30: =S30 -> 7 | BD30: =AA30+BC30 -> 7 | BF30: =VLOOKUP(C30,[1]Sheet!$F:$Q,9,FALSE) -> #N/A | BG30: =VLOOKUP(C30,[1]Sheet!$F:$Q,5,FALSE) -> #N/A | BH30: =VLOOKUP(C30,[1]Sheet!$F:$Q,12,FALSE) -> #N/A | BI30: =BG30-BH30 -> #N/A
A31: =ROW()-2 -> 29 | C31: WHLU5789206 | D31: WHL | E31: Kaidila | F31: MPM | G31: Sorento | H31: Lanyi | I31: 8503-RL+7603-SH-250+7603-SH-150+7603-SH-200+7603-SH-300+5202+206+1514+1516 | J31: 46208 | K31: 46211 | L31: 46213 | M31: 46221 | N31: 46225 | Q31: 14 | R31: + | S31: 7 | AI31: 10950 | AK31: =AJ31*1.4% -> 0 | AY31: XY 20/07/2026 02.29PM | BA31: =Q31 -> 14 | BB31: =N31+BA31-1 -> 46238 | BC31: =S31 -> 7 | BD31: =AA31+BC31 -> 7 | BF31: =VLOOKUP(C31,[1]Sheet!$F:$Q,9,FALSE) -> #N/A | BG31: =VLOOKUP(C31,[1]Sheet!$F:$Q,5,FALSE) -> #N/A | BH31: =VLOOKUP(C31,[1]Sheet!$F:$Q,12,FALSE) -> #N/A | BI31: =BG31-BH31 -> #N/A
A32: =ROW()-2 -> 30 | C32: WHSU6840437 | D32: WHL | E32: Kaidila | F32: MPM | G32: Sorento | H32: Lanyi+Jinbaichuan+Jiohol | I32: 8518-SH+8518-SH-200+8518-SH-P+1514+3430+3431+MSP231+286-SH-NEW+Sample Joihol | J32: 46208 | K32: 46211 | L32: 46213 | M32: 46221 | N32: 46225 | Q32: 14 | R32: + | S32: 7 | AI32: 10950 | AK32: =AJ32*1.4% -> 0 | AY32: XY 20/07/2026 02.29PM | BA32: =Q32 -> 14 | BB32: =N32+BA32-1 -> 46238 | BC32: =S32 -> 7 | BD32: =AA32+BC32 -> 7 | BF32: =VLOOKUP(C32,[1]Sheet!$F:$Q,9,FALSE) -> #N/A | BG32: =VLOOKUP(C32,[1]Sheet!$F:$Q,5,FALSE) -> #N/A | BH32: =VLOOKUP(C32,[1]Sheet!$F:$Q,12,FALSE) -> #N/A | BI32: =BG32-BH32 -> #N/A
A33: =ROW()-2 -> 31 | C33: WHSU8454921 | D33: WHL | E33: Kaidila | F33: MPM | G33: Sorento | H33: Lanyi | I33: 8518-SH+7614-RL+7614-RL-200 | J33: 46208 | K33: 46211 | L33: 46213 | M33: 46221 | N33: 46225 | Q33: 14 | R33: + | S33: 7 | AI33: 10950 | AK33: =AJ33*1.4% -> 0 | AY33: XY 20/07/2026 02.29PM | BA33: =Q33 -> 14 | BB33: =N33+BA33-1 -> 46238 | BC33: =S33 -> 7 | BD33: =AA33+BC33 -> 7 | BF33: =VLOOKUP(C33,[1]Sheet!$F:$Q,9,FALSE) -> #N/A | BG33: =VLOOKUP(C33,[1]Sheet!$F:$Q,5,FALSE) -> #N/A | BH33: =VLOOKUP(C33,[1]Sheet!$F:$Q,12,FALSE) -> #N/A | BI33: =BG33-BH33 -> #N/A
A34: =ROW()-2 -> 32 | C34: WHSU6517147 | D34: WHL | E34: Kaidila | F34: MPM | G34: Sorento (Full Mocha) | H34: Lanyi | I34: MWC7630-SH-S10+7630-SH-P+7630-SH-S12+7630-SH-S8 | J34: 46208 | K34: 46211 | L34: 46213 | M34: 46221 | N34: 46225 | Q34: 14 | R34: + | S34: 7 | AI34: 10950 | AK34: =AJ34*1.4% -> 0 | AY34: XY 20/07/2026 02.29PM | BA34: =Q34 -> 14 | BB34: =N34+BA34-1 -> 46238 | BC34: =S34 -> 7 | BD34: =AA34+BC34 -> 7 | BF34: =VLOOKUP(C34,[1]Sheet!$F:$Q,9,FALSE) -> #N/A | BG34: =VLOOKUP(C34,[1]Sheet!$F:$Q,5,FALSE) -> #N/A | BH34: =VLOOKUP(C34,[1]Sheet!$F:$Q,12,FALSE) -> #N/A | BI34: =BG34-BH34 -> #N/A
A35: =ROW()-2 -> 33 | C35: WHSU6696253 | D35: WHL | E35: J&H | F35: MPM | G35: Sorento | H35: Dafuyuan | I35: 888-NEW+8608-RL+1515+7055+8318-RL-N | J35: 46208 | K35: 46211 | L35: 46213 | M35: 46221 | N35: 46225 | Q35: 14 | R35: + | S35: 7 | T35: 46226 | AI35: 11000 | AK35: =AJ35*1.4% -> 0 | AY35: XY 20/07/2026 2.31PM | BA35: =Q35 -> 14 | BB35: =N35+BA35-1 -> 46238 | BC35: =S35 -> 7 | BD35: =AA35+BC35 -> 7 | BF35: =VLOOKUP(C35,[1]Sheet!$F:$Q,9,FALSE) -> #N/A | BG35: =VLOOKUP(C35,[1]Sheet!$F:$Q,5,FALSE) -> #N/A | BH35: =VLOOKUP(C35,[1]Sheet!$F:$Q,12,FALSE) -> #N/A | BI35: =BG35-BH35 -> #N/A
A36: =ROW()-2 -> 34 | C36: WHSU5264717 | D36: WHL | E36: J&H | F36: MPM | G36: Sorento | H36: Dafuyuan | I36: 188-S-250+7049+7099+8317-RL | J36: 46208 | K36: 46211 | L36: 46213 | M36: 46221 | N36: 46225 | Q36: 14 | R36: + | S36: 7 | T36: 46226 | AI36: 11000 | AK36: =AJ36*1.4% -> 0 | AY36: XY 20/07/2026 2.31PM | BA36: =Q36 -> 14 | BB36: =N36+BA36-1 -> 46238 | BC36: =S36 -> 7 | BD36: =AA36+BC36 -> 7 | BF36: =VLOOKUP(C36,[1]Sheet!$F:$Q,9,FALSE) -> #N/A | BG36: =VLOOKUP(C36,[1]Sheet!$F:$Q,5,FALSE) -> #N/A | BH36: =VLOOKUP(C36,[1]Sheet!$F:$Q,12,FALSE) -> #N/A | BI36: =BG36-BH36 -> #N/A
A37: =ROW()-2 -> 35 | C37: WHSU5485370 | D37: WHL | E37: J&H | F37: MPM | G37: Sorento | H37: Dafuyuan | I37: 604-S-RL-NEW | J37: 46208 | K37: 46211 | L37: 46213 | M37: 46221 | N37: 46225 | Q37: 14 | R37: + | S37: 7 | T37: 46226 | AI37: 11000 | AK37: =AJ37*1.4% -> 0 | AY37: XY 20/07/2026 2.31PM | BA37: =Q37 -> 14 | BB37: =N37+BA37-1 -> 46238 | BC37: =S37 -> 7 | BD37: =AA37+BC37 -> 7 | BF37: =VLOOKUP(C37,[1]Sheet!$F:$Q,9,FALSE) -> #N/A | BG37: =VLOOKUP(C37,[1]Sheet!$F:$Q,5,FALSE) -> #N/A | BH37: =VLOOKUP(C37,[1]Sheet!$F:$Q,12,FALSE) -> #N/A | BI37: =BG37-BH37 -> #N/A
A38: =ROW()-2 -> 36 | C38: CAIU4276283 | D38: WHL | E38: J&H | F38: MPM | G38: Sorento | H38: Dafuyuan | I38: 7604-P-RL-NEW+7604-S-RL-NEW+8605-RL+604-S-RL-NEW | J38: 46208 | K38: 46211 | L38: 46213 | M38: 46221 | N38: 46225 | Q38: 14 | R38: + | S38: 7 | T38: 46226 | AI38: 11000 | AK38: =AJ38*1.4% -> 0 | AY38: XY 20/07/2026 2.31PM | BA38: =Q38 -> 14 | BB38: =N38+BA38-1 -> 46238 | BC38: =S38 -> 7 | BD38: =AA38+BC38 -> 7 | BF38: =VLOOKUP(C38,[1]Sheet!$F:$Q,9,FALSE) -> #N/A | BG38: =VLOOKUP(C38,[1]Sheet!$F:$Q,5,FALSE) -> #N/A | BH38: =VLOOKUP(C38,[1]Sheet!$F:$Q,12,FALSE) -> #N/A | BI38: =BG38-BH38 -> #N/A
A39: =ROW()-2 -> 37 | C39: WHSU8779594 | D39: WHL | E39: J&H | F39: MPM | G39: Sorento | H39: Dafuyuan | I39: 8605-S-RL+7604-LID+905-BI-P+7651-NEW+7652-BL+6021-SH-MW+6021-SH-MG+BD501+RT-C230180+8317-RL-WEPLS+8317-RL | J39: 46208 | K39: 46211 | L39: 46213 | M39: 46221 | N39: 46225 | Q39: 14 | R39: + | S39: 7 | T39: 46226 | AI39: 11000 | AK39: =AJ39*1.4% -> 0 | AY39: XY 20/07/2026 2.31PM | BA39: =Q39 -> 14 | BB39: =N39+BA39-1 -> 46238 | BC39: =S39 -> 7 | BD39: =AA39+BC39 -> 7 | BF39: =VLOOKUP(C39,[1]Sheet!$F:$Q,9,FALSE) -> #N/A | BG39: =VLOOKUP(C39,[1]Sheet!$F:$Q,5,FALSE) -> #N/A | BH39: =VLOOKUP(C39,[1]Sheet!$F:$Q,12,FALSE) -> #N/A | BI39: =BG39-BH39 -> #N/A
A40: =ROW()-2 -> 38 | C40: CSNU7816634 | D40: OOCL | E40: Kaidila | F40: MPM | G40: Sorento | H40: Jinbaichuan | I40: 8152-SH-300 | J40: 46209 | K40: 46214 | L40: 46216 | M40: 46225 | N40: 46229 | Q40: 14 | R40: + | S40: 7 | AI40: 10880 | AK40: =AJ40*1.4% -> 0 | BA40: =Q40 -> 14 | BB40: =N40+BA40-1 -> 46242 | BC40: =S40 -> 7 | BD40: =AA40+BC40 -> 7 | BF40: =VLOOKUP(C40,[1]Sheet!$F:$Q,9,FALSE) -> #N/A | BG40: =VLOOKUP(C40,[1]Sheet!$F:$Q,5,FALSE) -> #N/A | BH40: =VLOOKUP(C40,[1]Sheet!$F:$Q,12,FALSE) -> #N/A | BI40: =BG40-BH40 -> #N/A
...

Sheet Arrived
A1: ARRIVED (Target 500 Containers) | J1: 2-4 DAYS BEFORE ETD | L1: 7-8 DAYS | Q1: TO WAIVE DEMURRAGE & DETENTION | T1: 2 DAYS AFTER CONT. REACHED APPLY INSP. | U1: 3 DAYS (NOT INCL INSP.) | V1: CHINA AGENT (IF LATE CHARGE THEM) | W1: PAPER APPROVED 1-2 DAYS | X1: SAME DAY PAY DUTY & APPLY E GATE PASS | Z1: 48HRS UPON GATE PASS RECEIVED | AB1: 48HRS UPON INFORMED | AC1: WITHIN 6 DAYS UPON EXIT GATE | AK1: 1.4% - 1.6% | AT1: 1.6 | AV1: CHARGES
A2: NO | B2: LOC | C2: CONTAINER | D2: LINER | E2: CHINA FORWARDER | F2: MALAYSIA FORWARDER | G2: CONSIGNEE | H2: FACTORY | I2: PRODUCT | J2: LOADING | K2: ETC | L2: ETD | M2: ETA | N2: ETA DELAY | O2: ATA | P2: STACKED | Q2: FREE DAYS AVAILABLE | T2: INSPECTION | U2: APPROVAL | V2: ORI DOC RECEIVED DATE | W2: K1 SUBMISSION | X2: GATEPASS | Y2: DELIVERY WAREHOUSE | Z2: YARD ARRIVALS | AA2: W/H ARRIVALS | AB2: INFORMED COLLECTION | AC2: COLLECTION | AD2: REMARKS 1 | AE2: REMARKS 2 | AF2: REMARKS 3 | AG2: 2ND LABOUR CHARGE | AH2: K1 RATE | AI2: CHINA FREIGHT (RMB) | AJ2: PRODUCT VALUE (RMB) | AK2: 0.014 | AL2: DATE RECEIVE K1 | AM2: SST AMOUNT | AN2: LOCAL CLEARANCE CHARGES | AO2: KOPI | AP2: DEMURRAGE | AQ2: PORT CHARGES | AR2: DETENTION | AS2: TOTAL LOCAL CLEARANCE | AT2: TOTAL FREIGHT | AU2: CARGO INSURANCE | AV2: SRT? MBS? BOTH? | AW2: LOCAL CLEARANCE CHARGES | AX2: USD | AY2: SST | BB2: Demurrange | BD2: Detention
A3: =ROW()-2 -> 1 | B3: DC1 | C3: MSDU7419719 | D3: MSC | E3: Onetouch | F3: Sataka | G3: Sorento | H3: Yanggang | J3: 46029 | K3: 46033 | L3: 46034 | M3: 46042 | N3: 46041 | Q3: 21 | R3: + | S3: 0 | X3: 46044 | AA3: 46050 | AB3: 46056 | AC3: 46058 | AI3: 10000 | AN3: =2700+50 -> 2750 | AQ3: 265 | BA3: =Q3 -> 21 | BB3: =N3+BA3-1 -> 46061 | BC3: =S3 -> 0 | BD3: =AA3+BC3 -> 46050 | BF3: =VLOOKUP(C3,[1]Sheet!$F:$Q,10,FALSE) -> I | BG3: =VLOOKUP(C3,[1]Sheet!$F:$Q,5,FALSE) -> 156827 | BH3: =VLOOKUP(C3,[1]Sheet!$F:$Q,12,FALSE) -> 0 | BI3: =BG3-BH3 -> 156827
A4: =ROW()-2 -> 2 | B4: MWH | C4: MSDU8634742 | D4: MSC | E4: Onetouch | F4: Sataka | G4: Sorento | H4: Yanggang | J4: 46029 | K4: 46033 | L4: 46034 | M4: 46042 | N4: 46042 | Q4: 21 | R4: + | S4: 0 | X4: 46044 | AA4: 46051 | AB4: 46053 | AC4: 46053 | AI4: 10000 | AN4: 2700 | AQ4: 366.3 | BA4: =Q4 -> 21 | BB4: =N4+BA4-1 -> 46062 | BC4: =S4 -> 0 | BD4: =AA4+BC4 -> 46051 | BF4: =VLOOKUP(C4,[1]Sheet!$F:$Q,10,FALSE) -> I | BG4: =VLOOKUP(C4,[1]Sheet!$F:$Q,5,FALSE) -> 186321 | BH4: =VLOOKUP(C4,[1]Sheet!$F:$Q,12,FALSE) -> 0 | BI4: =BG4-BH4 -> 186321
A5: =ROW()-2 -> 3 | B5: MWH | C5: MSNU9664232 | D5: MSC | E5: Onetouch | F5: Sataka | G5: Sorento | H5: Yanggang | J5: 46029 | K5: 46033 | L5: 46034 | M5: 46042 | N5: 46041 | Q5: 21 | R5: + | S5: 0 | X5: 46044 | AA5: 46053 | AB5: 46056 | AC5: 46056 | AI5: 10000 | AN5: 2700 | AQ5: 366.3 | BA5: =Q5 -> 21 | BB5: =N5+BA5-1 -> 46061 | BC5: =S5 -> 0 | BD5: =AA5+BC5 -> 46053 | BF5: =VLOOKUP(C5,[1]Sheet!$F:$Q,10,FALSE) -> I | BG5: =VLOOKUP(C5,[1]Sheet!$F:$Q,5,FALSE) -> 178540 | BH5: =VLOOKUP(C5,[1]Sheet!$F:$Q,12,FALSE) -> 0 | BI5: =BG5-BH5 -> 178540
A6: =ROW()-2 -> 4 | B6: BRW | C6: FCIU9273686 | D6: CMA | E6: Hongxin | F6: MPM | G6: Sorento (Mocha) | H6: Taiyang | J6: 46027 | K6: 46028 | L6: 46030 | M6: 46041 | N6: 46042 | Q6: 14 | R6: + | S6: 0 | X6: 46050 | AA6: 46052 | AB6: 46053 | AC6: 46053 | AI6: 10400 | AK6: =AJ6*1.4% -> 0 | AN6: =2700+162 -> 2862 | AP6: =640-640 -> 0 | AQ6: 366.3 | AU6: =447.53+26.85 -> 474.38 | BA6: =Q6 -> 14 | BB6: =N6+BA6-1 -> 46055 | BC6: =S6 -> 0 | BD6: =AA6+BC6 -> 46052 | BF6: =VLOOKUP(C6,[1]Sheet!$F:$Q,10,FALSE) -> I | BG6: =VLOOKUP(C6,[1]Sheet!$F:$Q,5,FALSE) -> 505616.1 | BH6: =VLOOKUP(C6,[1]Sheet!$F:$Q,12,FALSE) -> 0 | BI6: =BG6-BH6 -> 505616.1
A7: =ROW()-2 -> 5 | B7: BRW | C7: TLLU8782540 | D7: CMA | E7: Hongxin | F7: MPM | G7: Sorento | H7: Taiyang | J7: 46027 | K7: 46028 | L7: 46030 | M7: 46041 | N7: 46042 | Q7: 14 | R7: + | S7: 0 | X7: 46056 | AA7: 46056 | AB7: 46057 | AC7: 46058 | AI7: 10400 | AN7: =2700+162 -> 2862 | AQ7: 526.3 | AR7: 960 | AU7: =505.71+30.34 -> 536.05 | BA7: =Q7 -> 14 | BB7: =N7+BA7-1 -> 46055 | BC7: =S7 -> 0 | BD7: =AA7+BC7 -> 46056 | BF7: =VLOOKUP(C7,[1]Sheet!$F:$Q,10,FALSE) -> I | BG7: =VLOOKUP(C7,[1]Sheet!$F:$Q,5,FALSE) -> 773109.6 | BH7: =VLOOKUP(C7,[1]Sheet!$F:$Q,12,FALSE) -> 0 | BI7: =BG7-BH7 -> 773109.6
A8: =ROW()-2 -> 6 | B8: MWH | C8: WHSU8787305 | D8: WHL | E8: Haiian | F8: Haiian | G8: Sorento (Full Mocha) | H8: Jinbaichuan | I8: 7620+242+7621+7605-RL-P+7605-RL-200+7605-RL | J8: 46031 | K8: 46032 | L8: 46034 | M8: 46044 | N8: 46043 | Q8: 14 | R8: + | S8: 7 | T8: 46044 | U8: 46048 | X8: 46056 | AA8: 46056 | AB8: 46058 | AC8: 46059 | AI8: 10400 | AN8: =2700+500+260+1000+192 -> 4652 | AQ8: 452.5 | BA8: =Q8 -> 14 | BB8: =N8+BA8-1 -> 46056 | BC8: =S8 -> 7 | BD8: =AA8+BC8 -> 46063 | BF8: =VLOOKUP(C8,[1]Sheet!$F:$Q,10,FALSE) -> I | BG8: =VLOOKUP(C8,[1]Sheet!$F:$Q,5,FALSE) -> 610 | BH8: =VLOOKUP(C8,[1]Sheet!$F:$Q,12,FALSE) -> 0 | BI8: =BG8-BH8 -> 610
A9: =ROW()-2 -> 7 | B9: PSM | C9: WHSU8785323 | D9: WHL | E9: Haiian | F9: Haiian | G9: Sorento | H9: Jinbaichuan | I9: 605-RL | J9: 46031 | K9: 46032 | L9: 46034 | M9: 46044 | N9: 46043 | Q9: 14 | R9: + | S9: 7 | T9: 46044 | U9: 46048 | X9: 46056 | AA9: 46056 | AB9: 46057 | AC9: 46057 | AI9: 10400 | AN9: =2700+500+260+192 -> 3652 | AQ9: 452.5 | AU9: =592.07+35.52 -> 627.59 | BA9: =Q9 -> 14 | BB9: =N9+BA9-1 -> 46056 | BC9: =S9 -> 7 | BD9: =AA9+BC9 -> 46063 | BF9: =VLOOKUP(C9,[1]Sheet!$F:$Q,10,FALSE) -> I | BG9: =VLOOKUP(C9,[1]Sheet!$F:$Q,5,FALSE) -> 100935 | BH9: =VLOOKUP(C9,[1]Sheet!$F:$Q,12,FALSE) -> 0 | BI9: =BG9-BH9 -> 100935
A10: =ROW()-2 -> 8 | B10: BRW | C10: WHSU8785880 | D10: WHL | E10: Haiian | F10: Haiian | G10: Sorento | H10: Jinbaichuan | I10: 8354-SH-150+8354-SH-P+8354-SH-200+8354-SH+8152-SH | J10: 46031 | K10: 46032 | L10: 46034 | M10: 46044 | N10: 46043 | Q10: 14 | R10: + | S10: 7 | T10: 46044 | U10: 46048 | X10: 46056 | AA10: 46056 | AB10: 46059 | AC10: 46059 | AI10: 10400 | AN10: =2700+500+260+192 -> 3652 | AQ10: 452.5 | BA10: =Q10 -> 14 | BB10: =N10+BA10-1 -> 46056 | BC10: =S10 -> 7 | BD10: =AA10+BC10 -> 46063 | BF10: =VLOOKUP(C10,[1]Sheet!$F:$Q,10,FALSE) -> I | BG10: =VLOOKUP(C10,[1]Sheet!$F:$Q,5,FALSE) -> 119150 | BH10: =VLOOKUP(C10,[1]Sheet!$F:$Q,12,FALSE) -> 0 | BI10: =BG10-BH10 -> 119150
A11: =ROW()-2 -> 9 | B11: MWH | C11: WHSU8783038 | D11: WHL | E11: Haiian | F11: Haiian | G11: Sorento | H11: Jinbaichuan+Teca+Yimeijia+Jiahao | I11: CWB247+762+245++286-SH+286-SH-200+286-SH-150+189-G2+6012+1408+1455+1456+1549+1542 | J11: 46031 | K11: 46032 | L11: 46034 | M11: 46044 | N11: 46043 | Q11: 14 | R11: + | S11: 7 | T11: 46044 | U11: 46048 | X11: 46056 | AA11: 46057 | AB11: 46058 | AC11: 46058 | AI11: =10400+1000 -> 11400 | AN11: =2700+500+260+192 -> 3652 | AQ11: =327.5+198.8 -> 526.3 | BA11: =Q11 -> 14 | BB11: =N11+BA11-1 -> 46056 | BC11: =S11 -> 7 | BD11: =AA11+BC11 -> 46064 | BF11: =VLOOKUP(C11,[1]Sheet!$F:$Q,10,FALSE) -> I | BG11: =VLOOKUP(C11,[1]Sheet!$F:$Q,5,FALSE) -> 76777 | BH11: =VLOOKUP(C11,[1]Sheet!$F:$Q,12,FALSE) -> 0 | BI11: =BG11-BH11 -> 76777
A12: =ROW()-2 -> 10 | B12: PSM | C12: WHSU8784250 | D12: WHL | E12: Haiian | F12: Haiian | G12: Sorento (Full Mocha) | H12: Jinbaichuan | I12: 7625-SH-S10+7625-SH-P | J12: 46031 | K12: 46032 | L12: 46034 | M12: 46044 | N12: 46043 | Q12: 14 | R12: + | S12: 7 | T12: 46044 | U12: 46048 | X12: 46056 | AA12: 46057 | AB12: 46062 | AC12: 46062 | AI12: 10400 | AN12: =2700+500+260+192 -> 3652 | AQ12: =292.5+198.8 -> 491.3 | BA12: =Q12 -> 14 | BB12: =N12+BA12-1 -> 46056 | BC12: =S12 -> 7 | BD12: =AA12+BC12 -> 46064 | BF12: =VLOOKUP(C12,[1]Sheet!$F:$Q,10,FALSE) -> #N/A | BG12: =VLOOKUP(C12,[1]Sheet!$F:$Q,5,FALSE) -> #N/A | BH12: =VLOOKUP(C12,[1]Sheet!$F:$Q,12,FALSE) -> #N/A | BI12: =BG12-BH12 -> #N/A
A13: =ROW()-2 -> 11 | B13: BRW | C13: WHSU8793191 | D13: WHL | E13: Haiian | F13: Haiian | G13: Sorento | H13: Jinbaichuan | I13: 286-SH | J13: 46031 | K13: 46032 | L13: 46034 | M13: 46044 | N13: 46043 | Q13: 14 | R13: + | S13: 7 | T13: 46044 | U13: 46048 | X13: 46056 | AA13: 46057 | AB13: 46059 | AC13: 46059 | AI13: 10400 | AN13: =2700+162 -> 2862 | AP13: 230 | AQ13: =292.5+198.8 -> 491.3 | BA13: =Q13 -> 14 | BB13: =N13+BA13-1 -> 46056 | BC13: =S13 -> 7 | BD13: =AA13+BC13 -> 46064 | BF13: =VLOOKUP(C13,[1]Sheet!$F:$Q,10,FALSE) -> I | BG13: =VLOOKUP(C13,[1]Sheet!$F:$Q,5,FALSE) -> 111720 | BH13: =VLOOKUP(C13,[1]Sheet!$F:$Q,12,FALSE) -> 0 | BI13: =BG13-BH13 -> 111720
A14: =ROW()-2 -> 12 | B14: MWH | C14: WHSU8783059 | D14: WHL | E14: Haiian | F14: Haiian | G14: Sorento | H14: Jinbaichuan | I14: 287A-RL | J14: 46031 | K14: 46032 | L14: 46034 | M14: 46044 | N14: 46043 | Q14: 14 | R14: + | S14: 7 | T14: 46044 | U14: 46048 | X14: 46056 | AA14: 46058 | AB14: 46062 | AC14: 46062 | AI14: 10400 | AN14: =2700+500+260+192 -> 3652 | AP14: 184 | AQ14: =292.5+233.8 -> 526.3 | BA14: =Q14 -> 14 | BB14: =N14+BA14-1 -> 46056 | BC14: =S14 -> 7 | BD14: =AA14+BC14 -> 46065 | BF14: =VLOOKUP(C14,[1]Sheet!$F:$Q,10,FALSE) -> I | BG14: =VLOOKUP(C14,[1]Sheet!$F:$Q,5,FALSE) -> 102000 | BH14: =VLOOKUP(C14,[1]Sheet!$F:$Q,12,FALSE) -> 0 | BI14: =BG14-BH14 -> 102000
A15: =ROW()-2 -> 13 | B15: BRW | C15: OOLU6989170 | D15: COSCO | E15: Kaidila | F15: MPM | G15: Sorento (Mocha) | H15: Gaode | J15: 46027 | K15: 46032 | L15: 46034 | M15: 46045 | N15: 46043 | Q15: 21 | R15: + | S15: 0 | T15: 46043 | U15: 46048 | X15: 46058 | AA15: 46059 | AB15: 46060 | AC15: 46060 | AI15: =10400+1000 -> 11400 | AN15: =2700+162 -> 2862 | AQ15: 600 | BA15: =Q15 -> 21 | BB15: =N15+BA15-1 -> 46063 | BC15: =S15 -> 0 | BD15: =AA15+BC15 -> 46059 | BF15: =VLOOKUP(C15,[1]Sheet!$F:$Q,10,FALSE) -> I | BG15: =VLOOKUP(C15,[1]Sheet!$F:$Q,5,FALSE) -> 71800 | BH15: =VLOOKUP(C15,[1]Sheet!$F:$Q,12,FALSE) -> 0 | BI15: =BG15-BH15 -> 71800
A16: =ROW()-2 -> 14 | B16: MWH | C16: CSNU6595776 | D16: COSCO | E16: Kaidila | F16: MPM | G16: Sorento (Mocha) | H16: Weikaili+Gaode | J16: 46027 | K16: 46032 | L16: 46034 | M16: 46045 | N16: 46043 | Q16: 21 | R16: + | S16: 0 | T16: 46043 | U16: 46048 | X16: 46058 | AA16: 46060 | AB16: 46064 | AC16: 46064 | AI16: =10400+150+1000 -> 11550 | AN16: =2700+700+500+1000+63.6+192 -> 5155.6 | AO16: 2000 | AP16: =160+9.6 -> 169.6 | AQ16: 600 | AU16: =364.2+21.85 -> 386.05 | BA16: =Q16 -> 21 | BB16: =N16+BA16-1 -> 46063 | BC16: =S16 -> 0 | BD16: =AA16+BC16 -> 46060 | BF16: =VLOOKUP(C16,[1]Sheet!$F:$Q,10,FALSE) -> I | BG16: =VLOOKUP(C16,[1]Sheet!$F:$Q,5,FALSE) -> 31600 | BH16: =VLOOKUP(C16,[1]Sheet!$F:$Q,12,FALSE) -> 0 | BI16: =BG16-BH16 -> 31600
A17: =ROW()-2 -> 15 | B17: MWH | C17: CSNU8281286 | D17: COSCO | E17: Kaidila | F17: MPM | G17: Sorento (Full Mocha) | H17: Weikaili | J17: 46027 | K17: 46032 | L17: 46034 | M17: 46045 | N17: 46043 | Q17: 21 | R17: + | S17: 0 | T17: 46043 | U17: 46048 | X17: 46058 | AA17: 46063 | AC17: 46065 | AI17: 10400 | AN17: =2700+162 -> 2862 | AP17: =320+19.2 -> 339.2 | AQ17: 745 | BA17: =Q17 -> 21 | BB17: =N17+BA17-1 -> 46063 | BC17: =S17 -> 0 | BD17: =AA17+BC17 -> 46063 | BF17: =VLOOKUP(C17,[1]Sheet!$F:$Q,10,FALSE) -> #N/A | BG17: =VLOOKUP(C17,[1]Sheet!$F:$Q,5,FALSE) -> #N/A | BH17: =VLOOKUP(C17,[1]Sheet!$F:$Q,12,FALSE) -> #N/A | BI17: =BG17-BH17 -> #N/A
A18: =ROW()-2 -> 16 | B18: MWH | C18: FCIU9602971 | D18: COSCO | E18: Kaidila | F18: MPM | G18: Sorento (Mocha) | H18: Gaode+Jinbaichuan | J18: 46027 | K18: 46032 | L18: 46034 | M18: 46045 | N18: 46043 | Q18: 21 | R18: + | S18: 0 | T18: 46043 | U18: 46048 | X18: 46058 | AA18: 46065 | AB18: 46072 | AC18: 46072 | AI18: =10400+150+1000 -> 11550 | AN18: =2700+700+500+192 -> 4092 | AP18: =1860+111.6 -> 1971.6 | AQ18: 839.1 | BA18: =Q18 -> 21 | BB18: =N18+BA18-1 -> 46063 | BC18: =S18 -> 0 | BD18: =AA18+BC18 -> 46065 | BF18: =VLOOKUP(C18,[1]Sheet!$F:$Q,10,FALSE) -> I | BG18: =VLOOKUP(C18,[1]Sheet!$F:$Q,5,FALSE) -> 58400 | BH18: =VLOOKUP(C18,[1]Sheet!$F:$Q,12,FALSE) -> 0 | BI18: =BG18-BH18 -> 58400
A19: =ROW()-2 -> 17 | B19: MWH | C19: DFSU7049428 | D19: COSCO | E19: Kaidila | F19: MPM | G19: Sorento (Full Mocha) | H19: Weikaili | J19: 46027 | K19: 46032 | L19: 46034 | M19: 46045 | N19: 46043 | Q19: 21 | R19: + | S19: 0 | T19: 46043 | U19: 46048 | X19: 46058 | AA19: 46064 | AB19: 46065 | AC19: 46065 | AI19: 10400 | AN19: =2700+162 -> 2862 | AP19: =320+19.2 -> 339.2 | AQ19: 839.1 | BA19: =Q19 -> 21 | BB19: =N19+BA19-1 -> 46063 | BC19: =S19 -> 0 | BD19: =AA19+BC19 -> 46064 | BF19: =VLOOKUP(C19,[1]Sheet!$F:$Q,10,FALSE) -> #N/A | BG19: =VLOOKUP(C19,[1]Sheet!$F:$Q,5,FALSE) -> #N/A | BH19: =VLOOKUP(C19,[1]Sheet!$F:$Q,12,FALSE) -> #N/A | BI19: =BG19-BH19 -> #N/A
A20: =ROW()-2 -> 18 | B20: DC1 | C20: OOCU6812825 | D20: OOCL | E20: J&H | F20: MPM | G20: Sorento | H20: Lanyi | I20: 7630-SH+7630-SH-200+7630-SH-300+8503-RL+8517-SH+7624-RL-S10+1409-BL+1518+1086-CB+1215+1219+1409-CB+1411-CB+1421-CB+1515-CB+1086+1411+7237+7018 | J20: 46025 | K20: 46035 | L20: 46037 | M20: 46043 | N20: 46048 | Q20: 14 | R20: + | S20: 7 | T20: 46049 | U20: 46050 | X20: 46059 | AA20: 46060 | AB20: 46064 | AC20: 46068 | AI20: 11600 | AN20: =2700+700+500+1000+127.2+192 -> 5219.2 | AQ20: 452.5 | AR20: =63.6-63.6 -> 0 | AU20: =359.73+21.58 -> 381.31 | BA20: =Q20 -> 14 | BB20: =N20+BA20-1 -> 46061 | BC20: =S20 -> 7 | BD20: =AA20+BC20 -> 46067 | BF20: =VLOOKUP(C20,[1]Sheet!$F:$Q,10,FALSE) -> I | BG20: =VLOOKUP(C20,[1]Sheet!$F:$Q,5,FALSE) -> 120943.02 | BH20: =VLOOKUP(C20,[1]Sheet!$F:$Q,12,FALSE) -> 0 | BI20: =BG20-BH20 -> 120943.02
A21: =ROW()-2 -> 19 | B21: DC1 | C21: CSNU6403493 | D21: OOCL | E21: J&H | F21: MPM | G21: Sorento | H21: Lanyi | I21: 8518-SH+8518-SH-P+1514 | J21: 46025 | K21: 46035 | L21: 46037 | M21: 46043 | N21: 46048 | Q21: 14 | R21: + | S21: 7 | T21: 46049 | U21: 46050 | X21: 46058 | AA21: 46060 | AB21: 46066 | AC21: 46066 | AI21: 11600 | AN21: =2700+700+500+192 -> 4092 | AQ21: 452.5 | BA21: =Q21 -> 14 | BB21: =N21+BA21-1 -> 46061 | BC21: =S21 -> 7 | BD21: =AA21+BC21 -> 46067 | BF21: =VLOOKUP(C21,[1]Sheet!$F:$Q,10,FALSE) -> I | BG21: =VLOOKUP(C21,[1]Sheet!$F:$Q,5,FALSE) -> 131884.96 | BH21: =VLOOKUP(C21,[1]Sheet!$F:$Q,12,FALSE) -> 0 | BI21: =BG21-BH21 -> 131884.96
A22: =ROW()-2 -> 20 | B22: MWH | C22: CCLU7720154 | D22: OOCL | E22: J&H | F22: MPM | G22: Sorento (Full Mocha) | H22: Lanyi | I22: 7630-SH-S10+7630-SH-S8+7630-SH-P+7630-SH-S6 | J22: 46025 | K22: 46035 | L22: 46037 | M22: 46043 | N22: 46047 | Q22: 14 | R22: + | S22: 7 | T22: 46049 | U22: 46050 | X22: 46058 | AA22: 46063 | AB22: 46073 | AC22: 46073 | AI22: 11600 | AN22: =2700+700+500+192 -> 4092 | AP22: =465+27.9 -> 492.9 | AQ22: 600 | AR22: =240+14.4 -> 254.4 | BA22: =Q22 -> 14 | BB22: =N22+BA22-1 -> 46060 | BC22: =S22 -> 7 | BD22: =AA22+BC22 -> 46070 | BF22: =VLOOKUP(C22,[1]Sheet!$F:$Q,10,FALSE) -> #N/A | BG22: =VLOOKUP(C22,[1]Sheet!$F:$Q,5,FALSE) -> #N/A | BH22: =VLOOKUP(C22,[1]Sheet!$F:$Q,12,FALSE) -> #N/A | BI22: =BG22-BH22 -> #N/A
A23: =ROW()-2 -> 21 | B23: PSM | C23: OOCU5851386 | D23: OOCL | E23: J&H | F23: MPM | G23: Sorento (Full Mocha) | H23: Lanyi | I23: 7614-RL-S10+7614-RL-S8+7624-RL-S10+7624-RL-P+7023+7024+7045-WH+7048-WH+7046+7755+7044-BL+7044-WH+7046-BL+7762-BL+SP231 | J23: 46025 | K23: 46035 | L23: 46037 | M23: 46043 | N23: 46047 | Q23: 14 | R23: + | S23: 7 | T23: 46049 | U23: 46050 | X23: 46058 | AA23: 46063 | AB23: 46066 | AC23: 46068 | AI23: 11600 | AN23: =2700+700+500+192 -> 4092 | AP23: =310+18.6 -> 328.6 | AQ23: 600 | BA23: =Q23 -> 14 | BB23: =N23+BA23-1 -> 46060 | BC23: =S23 -> 7 | BD23: =AA23+BC23 -> 46070 | BF23: =VLOOKUP(C23,[1]Sheet!$F:$Q,10,FALSE) -> #N/A | BG23: =VLOOKUP(C23,[1]Sheet!$F:$Q,5,FALSE) -> #N/A | BH23: =VLOOKUP(C23,[1]Sheet!$F:$Q,12,FALSE) -> #N/A | BI23: =BG23-BH23 -> #N/A
A24: =ROW()-2 -> 22 | B24: MWH | C24: DFSU7577997 | D24: COSCO | E24: J&H | F24: MPM | G24: Sorento | H24: Jinbaichuan | I24: 243 | J24: 46027 | K24: 46031 | L24: 46032 | M24: 46039 | N24: 46043 | Q24: 21 | R24: + | S24: 0 | T24: 46044 | U24: 46048 | X24: 46058 | AA24: 46060 | AB24: 46065 | AC24: 46065 | AI24: =10450+1000 -> 11450 | AN24: =2700+700+500+192 -> 4092 | AP24: =320+19.2 -> 339.2 | AQ24: 600 | AU24: =635.22+38.11 -> 673.33 | BA24: =Q24 -> 21 | BB24: =N24+BA24-1 -> 46063 | BC24: =S24 -> 0 | BD24: =AA24+BC24 -> 46060 | BF24: =VLOOKUP(C24,[1]Sheet!$F:$Q,10,FALSE) -> I | BG24: =VLOOKUP(C24,[1]Sheet!$F:$Q,5,FALSE) -> 81097.45 | BH24: =VLOOKUP(C24,[1]Sheet!$F:$Q,12,FALSE) -> 0 | BI24: =BG24-BH24 -> 81097.45
A25: =ROW()-2 -> 23 | B25: MWH | C25: CSNU7567911 | D25: COSCO | E25: J&H | F25: MPM | G25: Sorento | H25: Jinbaichuan | I25: 286-SH | J25: 46027 | K25: 46031 | L25: 46032 | M25: 46039 | N25: 46043 | Q25: 21 | R25: + | S25: 0 | T25: 46044 | U25: 46048 | X25: 46058 | AA25: 46060 | AB25: 46063 | AC25: 46063 | AI25: 10450 | AN25: =2700+162 -> 2862 | AQ25: 600 | BA25: =Q25 -> 21 | BB25: =N25+BA25-1 -> 46063 | BC25: =S25 -> 0 | BD25: =AA25+BC25 -> 46060 | BF25: =VLOOKUP(C25,[1]Sheet!$F:$Q,10,FALSE) -> I | BG25: =VLOOKUP(C25,[1]Sheet!$F:$Q,5,FALSE) -> 111720 | BH25: =VLOOKUP(C25,[1]Sheet!$F:$Q,12,FALSE) -> 0 | BI25: =BG25-BH25 -> 111720
A26: =ROW()-2 -> 24 | B26: DC1 | C26: OOCU9005391 | D26: COSCO | E26: J&H | F26: MPM | G26: Sorento | H26: Jinbaichuan | I26: 9032+242+24+7518+890+241+SP124+7405-SC+BD325+1210 | J26: 46027 | K26: 46031 | L26: 46032 | M26: 46039 | N26: 46043 | Q26: 21 | R26: + | S26: 0 | T26: 46044 | U26: 46048 | X26: 46058 | AA26: 46060 | AB26: 46063 | AC26: 46064 | AI26: =10450+1000 -> 11450 | AN26: =2700+700+500+192 -> 4092 | AP26: =160+9.6 -> 169.6 | AQ26: 600 | BA26: =Q26 -> 21 | BB26: =N26+BA26-1 -> 46063 | BC26: =S26 -> 0 | BD26: =AA26+BC26 -> 46060 | BF26: =VLOOKUP(C26,[1]Sheet!$F:$Q,10,FALSE) -> I | BG26: =VLOOKUP(C26,[1]Sheet!$F:$Q,5,FALSE) -> 105760.02 | BH26: =VLOOKUP(C26,[1]Sheet!$F:$Q,12,FALSE) -> 0 | BI26: =BG26-BH26 -> 105760.02
A27: =ROW()-2 -> 25 | B27: DC1 | C27: CSNU8989824 | D27: COSCO | E27: J&H | F27: MPM | G27: Sorento | H27: Jinbaichuan | I27: 7606-SH | J27: 46027 | K27: 46031 | L27: 46032 | M27: 46039 | N27: 46043 | Q27: 21 | R27: + | S27: 0 | T27: 46044 | U27: 46048 | X27: 46058 | AA27: 46060 | AB27: 46062 | AC27: 46063 | AI27: 10450 | AN27: =2700+700+500+192 -> 4092 | AQ27: 600 | BA27: =Q27 -> 21 | BB27: =N27+BA27-1 -> 46063 | BC27: =S27 -> 0 | BD27: =AA27+BC27 -> 46060 | BF27: =VLOOKUP(C27,[1]Sheet!$F:$Q,10,FALSE) -> I | BG27: =VLOOKUP(C27,[1]Sheet!$F:$Q,5,FALSE) -> 89100 | BH27: =VLOOKUP(C27,[1]Sheet!$F:$Q,12,FALSE) -> 0 | BI27: =BG27-BH27 -> 89100
A28: =ROW()-2 -> 26 | B28: BRW | C28: OOLU9279402 | D28: COSCO | E28: J&H | F28: MPM | G28: Sorento | H28: Jinbaichuan | I28: 286-SH+286-SH-200 | J28: 46027 | K28: 46031 | L28: 46032 | M28: 46039 | N28: 46043 | Q28: 21 | R28: + | S28: 0 | T28: 46044 | U28: 46048 | X28: 46058 | AA28: 46060 | AB28: 46062 | AC28: 46062 | AI28: 10450 | AN28: =2700+700+500+1000+190.8+192 -> 5282.8 | AQ28: 636.3 | BA28: =Q28 -> 21 | BB28: =N28+BA28-1 -> 46063 | BC28: =S28 -> 0 | BD28: =AA28+BC28 -> 46060 | BF28: =VLOOKUP(C28,[1]Sheet!$F:$Q,10,FALSE) -> I | BG28: =VLOOKUP(C28,[1]Sheet!$F:$Q,5,FALSE) -> 111720 | BH28: =VLOOKUP(C28,[1]Sheet!$F:$Q,12,FALSE) -> 0 | BI28: =BG28-BH28 -> 111720
A29: =ROW()-2 -> 27 | B29: DC1 | C29: CSNU8793256 | D29: COSCO | E29: J&H | F29: MPM | G29: Sorento | H29: Jinbaichuan | I29: 8152-SH-150+8152-SH | J29: 46027 | K29: 46031 | L29: 46032 | M29: 46039 | N29: 46043 | Q29: 21 | R29: + | S29: 0 | T29: 46044 | U29: 46048 | X29: 46058 | AA29: 46060 | AB29: 46063 | AC29: 46063 | AI29: 10450 | AN29: =2700+700+500+192 -> 4092 | AQ29: 600 | BA29: =Q29 -> 21 | BB29: =N29+BA29-1 -> 46063 | BC29: =S29 -> 0 | BD29: =AA29+BC29 -> 46060 | BF29: =VLOOKUP(C29,[1]Sheet!$F:$Q,10,FALSE) -> I | BG29: =VLOOKUP(C29,[1]Sheet!$F:$Q,5,FALSE) -> 112800 | BH29: =VLOOKUP(C29,[1]Sheet!$F:$Q,12,FALSE) -> 0 | BI29: =BG29-BH29 -> 112800
